Workbook
Name mm: plan!$AN$88

Sheet plan
C1: določi ure proizvodnje | J1: 24 | N1: 24 | R1: 24 | V1: 24 | Z1: 24 | AD1: 24 | AH1: 24 | AL1: 24 | AP1: 24 | AT1: 24 | AX1: 24 | BB1: 24 | BF1: 24 | BJ1: 24 | BN1: 24 | BR1: 24 | BV1: 24 | BZ1: 24 | CD1: 24 | CH1: 24 | CL1: 24 | CP1: 24 | CT1: 24 | CX1: 24 | DB1: 24 | DF1: 24 | DJ1: 24 | DN1: 24 | DR1: 24
H4: 45873 | L4: =IF(WEEKDAY(H4,2)=5,H4+3,H4+1) -> 45874 | P4: =IF(WEEKDAY(L4,2)=5,L4+3,L4+1) -> 45875 | T4: =IF(WEEKDAY(P4,2)=5,P4+3,P4+1) -> 45876 | X4: =IF(WEEKDAY(T4,2)=5,T4+3,T4+1) -> 45877 | AB4: =IF(WEEKDAY(X4,2)=5,X4+3,X4+1) -> 45880 | AF4: =IF(WEEKDAY(AB4,2)=5,AB4+3,AB4+1) -> 45881 | AJ4: =IF(WEEKDAY(AF4,2)=5,AF4+3,AF4+1) -> 45882 | AN4: =IF(WEEKDAY(AJ4,2)=5,AJ4+3,AJ4+1) -> 45883 | AR4: 45887 | AV4: =IF(WEEKDAY(AR4,2)=5,AR4+3,AR4+1) -> 45888 | AZ4: =IF(WEEKDAY(AV4,2)=5,AV4+3,AV4+1) -> 45889 | BD4: =IF(WEEKDAY(AZ4,2)=5,AZ4+3,AZ4+1) -> 45890 | BH4: =IF(WEEKDAY(BD4,2)=5,BD4+3,BD4+1) -> 45891 | BL4: =IF(WEEKDAY(BH4,2)=5,BH4+3,BH4+1) -> 45894 | BP4: =IF(WEEKDAY(BL4,2)=5,BL4+3,BL4+1) -> 45895 | BT4: =IF(WEEKDAY(BP4,2)=5,BP4+3,BP4+1) -> 45896 | BX4: =IF(WEEKDAY(BT4,2)=5,BT4+3,BT4+1) -> 45897 | CB4: =IF(WEEKDAY(BX4,2)=5,BX4+3,BX4+1) -> 45898 | CF4: =IF(WEEKDAY(CB4,2)=5,CB4+3,CB4+1) -> 45901 | CJ4: =IF(WEEKDAY(CF4,2)=5,CF4+3,CF4+1) -> 45902 | CN4: =IF(WEEKDAY(CJ4,2)=5,CJ4+3,CJ4+1) -> 45903 | CR4: =IF(WEEKDAY(CN4,2)=5,CN4+3,CN4+1) -> 45904 | CV4: =IF(WEEKDAY(CR4,2)=5,CR4+3,CR4+1) -> 45905 | CZ4: =IF(WEEKDAY(CV4,2)=5,CV4+3,CV4+1) -> 45908 | DD4: =IF(WEEKDAY(CZ4,2)=5,CZ4+3,CZ4+1) -> 45909 | DH4: =IF(WEEKDAY(DD4,2)=5,DD4+3,DD4+1) -> 45910 | DL4: =IF(WEEKDAY(DH4,2)=5,DH4+3,DH4+1) -> 45911 | DP4: =IF(WEEKDAY(DL4,2)=5,DL4+3,DL4+1) -> 45912
C5: Status plana | H5: =IF(D4<=$C$55,"Fiksno","V pripravi") -> Fiksno | L5: =IF(H4<=$C$55,"Fiksno","V pripravi") -> Fiksno | P5: =IF(L4<=$C$55,"Fiksno","V pripravi") -> Fiksno | T5: =IF(P4<=$C$55,"Fiksno","V pripravi") -> Fiksno | X5: =IF(T4<=$C$55,"Fiksno","V pripravi") -> Fiksno | AB5: =IF(X4<=$C$55,"Fiksno","V pripravi") -> Fiksno | AF5: =IF(AB4<=$C$55,"Fiksno","V pripravi") -> Fiksno | AJ5: =IF(AF4<=$C$55,"Fiksno","V pripravi") -> Fiksno | AN5: =IF(AJ4<=$C$55,"Fiksno","V pripravi") -> Fiksno | AR5: =IF(AN4<=$C$55,"Fiksno","V pripravi") -> V pripravi | AV5: =IF(AR4<=$C$55,"Fiksno","V pripravi") -> V pripravi | AZ5: =IF(AV4<=$C$55,"Fiksno","V pripravi") -> V pripravi | BD5: =IF(AZ4<=$C$55,"Fiksno","V pripravi") -> V pripravi | BH5: =IF(BD4<=$C$55,"Fiksno","V pripravi") -> V pripravi | BL5: =IF(BH4<=$C$55,"Fiksno","V pripravi") -> V pripravi | BP5: =IF(BL4<=$C$55,"Fiksno","V pripravi") -> V pripravi | BT5: =IF(BP4<=$C$55,"Fiksno","V pripravi") -> V pripravi | BX5: =IF(BT4<=$C$55,"Fiksno","V pripravi") -> V pripravi | CB5: =IF(BX4<=$C$55,"Fiksno","V pripravi") -> V pripravi | CF5: =IF(CB4<=$C$55,"Fiksno","V pripravi") -> V pripravi | CJ5: =IF(CF4<=$C$55,"Fiksno","V pripravi") -> V pripravi | CN5: =IF(CJ4<=$C$55,"Fiksno","V pripravi") -> V pripravi | CR5: =IF(CN4<=$C$55,"Fiksno","V pripravi") -> V pripravi | CV5: =IF(CR4<=$C$55,"Fiksno","V pripravi") -> V pripravi | CZ5: =IF(CV4<=$C$55,"Fiksno","V pripravi") -> V pripravi | DD5: =IF(CZ4<=$C$55,"Fiksno","V pripravi") -> V pripravi | DH5: =IF(DD4<=$C$55,"Fiksno","V pripravi") -> V pripravi | DL5: =IF(DH4<=$C$55,"Fiksno","V pripravi") -> V pripravi | DP5: =IF(DL4<=$C$55,"Fiksno","V pripravi") -> V pripravi
B6: Stroji za brizganje | E6: =D4 -> 0 | F6: posluž: | G6: =SUM(G9:G52) -> 0 | I6: =H4 -> 45873 | J6: posluž: | K6: =SUM(K9:K52) -> 3.75 | M6: =L4 -> 45874 | N6: posluž: | O6: =SUM(O9:O52) -> 4.5 | Q6: =P4 -> 45875 | R6: posluž: | S6: =SUM(S9:S52) -> 4.5 | U6: =T4 -> 45876 | V6: posluž: | W6: =SUM(W9:W52) -> 4.5 | Y6: =X4 -> 45877 | Z6: posluž: | AA6: =SUM(AA9:AA52) -> 4.25 | AC6: =AB4 -> 45880 | AD6: posluž: | AE6: =SUM(AE9:AE52) -> 4.5 | AG6: =AF4 -> 45881 | AH6: posluž: | AI6: =SUM(AI9:AI52) -> 4.75 | AK6: =AJ4 -> 45882 | AL6: posluž: | AM6: =SUM(AM9:AM52) -> 4.75 | AO6: =AN4 -> 45883 | AP6: posluž: | AQ6: =SUM(AQ9:AQ52) -> 4.25 | AS6: =AR4 -> 45887 | AT6: posluž: | AU6: =SUM(AU9:AU52) -> 3.5 | AW6: =AV4 -> 45888 | AX6: posluž: | AY6: =SUM(AY9:AY52) -> 2 | BA6: =AZ4 -> 45889 | BB6: posluž: | BC6: =SUM(BC9:BC52) -> 2.5 | BE6: =BD4 -> 45890 | BF6: posluž: | BG6: =SUM(BG9:BG52) -> 3.5 | BI6: =BH4 -> 45891 | BJ6: posluž: | BK6: =SUM(BK9:BK52) -> 3.5 | BM6: =BL4 -> 45894 | BN6: posluž: | BO6: =SUM(BO9:BO52) -> 2.5 | BQ6: =BP4 -> 45895 | BR6: posluž: | BS6: =SUM(BS9:BS52) -> 2.25 | BU6: =BT4 -> 45896 | BV6: posluž: | BW6: =SUM(BW9:BW52) -> 2.5 | BY6: =BX4 -> 45897 | BZ6: posluž: | CA6: =SUM(CA9:CA52) -> 3 | CC6: =CB4 -> 45898 | CD6: posluž: | CE6: =SUM(CE9:CE52) -> 2.5 | CG6: =CF4 -> 45901 | CH6: posluž: | CI6: =SUM(CI9:CI52) -> 3.25 | CK6: =CJ4 -> 45902 | CL6: posluž: | CM6: =SUM(CM9:CM52) -> 3.25 | CO6: =CN4 -> 45903 | CP6: posluž: | CQ6: =SUM(CQ9:CQ52) -> 3.25 | CS6: =CR4 -> 45904 | CT6: posluž: | CU6: =SUM(CU9:CU52) -> 2.25 | CW6: =CV4 -> 45905 | CX6: posluž: | CY6: =SUM(CY9:CY52) -> 0.75 | DA6: =CZ4 -> 45908 | DB6: posluž: | DC6: =SUM(DC9:DC52) -> 0 | DE6: =DD4 -> 45909 | DF6: posluž: | DG6: =SUM(DG9:DG52) -> 0 | DI6: =DH4 -> 45910 | DJ6: posluž: | DK6: =SUM(DK9:DK52) -> 0 | DM6: =DL4 -> 45911 | DN6: posluž: | DO6: =SUM(DO9:DO52) -> 0 | DQ6: =DP4 -> 45912 | DR6: posluž: | DS6: =SUM(DS9:DS52) -> 0
F7: menjav | G7: =E67 -> #REF! | H7: =I68 -> 0.55555556 | J7: menjav | K7: =I67 -> 8 | L7: =M68 -> 0.38888889 | N7: menjav | O7: =M67 -> 4 | P7: =Q68 -> 0.33333333 | R7: menjav | S7: =Q67 -> 3 | T7: =U68 -> 0.33333333 | V7: menjav | W7: =U67 -> 4 | X7: =Y68 -> 0.38888889 | Z7: menjav | AA7: =Y67 -> 2 | AB7: =AC68 -> 0.5 | AD7: menjav | AE7: =AC67 -> 2 | AF7: =AG68 -> 0.44444444 | AH7: menjav | AI7: =AG67 -> 3 | AJ7: =AK68 -> 0.44444444 | AL7: menjav | AM7: =AK67 -> 0 | AN7: =AO68 -> 0.44444444 | AP7: menjav | AQ7: =AO67 -> 2 | AR7: =AS68 -> 0.61111111 | AT7: menjav | AU7: =AS67 -> 4 | AV7: =AW68 -> 0.61111111 | AX7: menjav | AY7: =AW67 -> 2 | AZ7: =BA68 -> 0.61111111 | BB7: menjav | BC7: =BA67 -> 2 | BD7: =BE68 -> 0.5 | BF7: menjav | BG7: =BE67 -> 2 | BH7: =BI68 -> 0.5 | BJ7: menjav | BK7: =BI67 -> 0 | BL7: =BM68 -> 0.66666667 | BN7: menjav | BO7: =BM67 -> 2 | BP7: =BQ68 -> 0.77777778 | BR7: menjav | BS7: =BQ67 -> 1 | BT7: =BU68 -> 0.72222222 | BV7: menjav | BW7: =BU67 -> 1 | BX7: =BY68 -> 0.72222222 | BZ7: menjav | CA7: =BY67 -> 1 | CB7: =CC68 -> 0.77777778 | CD7: menjav | CE7: =CC67 -> 1 | CF7: =CG68 -> 0.72222222 | CH7: menjav | CI7: =CG67 -> 3 | CJ7: =CK68 -> 0.72222222 | CL7: menjav | CM7: =CK67 -> 2 | CN7: =CO68 -> 0.72222222 | CP7: menjav | CQ7: =CO67 -> 1 | CR7: =CS68 -> 0.83333333 | CT7: menjav | CU7: =CS67 -> 0 | CV7: =CW68 -> 0.88888889 | CX7: menjav | CY7: =CW67 -> 0 | CZ7: =DA68 -> 1 | DB7: menjav | DC7: =DA67 -> 0 | DD7: =DE68 -> 1 | DF7: menjav | DG7: =DE67 -> 0 | DH7: =DI68 -> 1 | DJ7: menjav | DK7: =DI67 -> 0 | DL7: =DM68 -> 1 | DN7: menjav | DO7: =DM67 -> 0 | DP7: =DQ68 -> 1 | DR7: menjav | DS7: =DQ67 -> 0
B8: št.stroja | C8: stroj | D8: šifra | E8: opis | F8: KOS/dan | G8: posl/stroj | H8: šifra | I8: opis | J8: KOS/dan | K8: posl/stroj | L8: šifra | M8: opis | N8: KOS/dan | O8: posl/stroj | P8: šifra | Q8: opis | R8: KOS/dan | S8: posl/stroj | T8: šifra | U8: opis | V8: KOS/dan | W8: posl/stroj | X8: šifra | Y8: opis | Z8: KOS/dan | AA8: posl/stroj | AB8: šifra | AC8: opis | AD8: KOS/dan | AE8: posl/stroj | AF8: šifra | AG8: opis | AH8: KOS/dan | AI8: posl/stroj | AJ8: šifra | AK8: opis | AL8: KOS/dan | AM8: posl/stroj | AN8: šifra | AO8: opis | AP8: KOS/dan | AQ8: posl/stroj | AR8: šifra | AS8: opis | AT8: KOS/dan | AU8: posl/stroj | AV8: šifra | AW8: opis | AX8: KOS/dan | AY8: posl/stroj | AZ8: šifra | BA8: opis | BB8: KOS/dan | BC8: posl/stroj | BD8: šifra | BE8: opis | BF8: KOS/dan | BG8: posl/stroj | BH8: šifra | BI8: opis | BJ8: KOS/dan | BK8: posl/stroj | BL8: šifra | BM8: opis | BN8: KOS/dan | BO8: posl/stroj | BP8: šifra | BQ8: opis | BR8: KOS/dan | BS8: posl/stroj | BT8: šifra | BU8: opis | BV8: KOS/dan | BW8: posl/stroj | BX8: šifra | BY8: opis | BZ8: KOS/dan | CA8: posl/stroj | CB8: šifra | CC8: opis | CD8: KOS/dan | CE8: posl/stroj | CF8: šifra | CG8: opis | CH8: KOS/dan | CI8: posl/stroj | CJ8: šifra | CK8: opis | CL8: KOS/dan | CM8: posl/stroj | CN8: šifra | CO8: opis | CP8: KOS/dan | CQ8: posl/stroj | CR8: šifra | CS8: opis | CT8: KOS/dan | CU8: posl/stroj | CV8: šifra | CW8: opis | CX8: KOS/dan | CY8: posl/stroj | CZ8: šifra | DA8: opis | DB8: KOS/dan | DC8: posl/stroj | DD8: šifra | DE8: opis | DF8: KOS/dan | DG8: posl/stroj | DH8: šifra | DI8: opis | DJ8: KOS/dan | DK8: posl/stroj | DL8: šifra | DM8: opis | DN8: KOS/dan | DO8: posl/stroj | DP8: šifra | DQ8: opis | DR8: KOS/dan | DS8: posl/stroj
A9: HALA 2 | B9: 1 | C9: KM 420 R | E9: =IF(D9=0,"0",VLOOKUP(D9,struktura!$B:$D,3,FALSE)) -> 0 | F9: =IF(D9=0,"",24/VLOOKUP(D9,struktura!$B:$F,5,FALSE)) | G9: =VLOOKUP(D9,struktura!$B:$G,6,FALSE) -> 0 | H9: 132100588 | I9: BUS CASE TOP II V2 | J9: 2769.2308 | K9: 0.5 | L9: 132100588 | M9: =IF(L9=0,0,VLOOKUP(L9,struktura!$B:$D,3,FALSE)) -> BUS CASE TOP II V2 | N9: =IF(L9=0,0,N$1/VLOOKUP(L9,struktura!$B:$F,5,FALSE)) -> 2769.2308 | O9: =VLOOKUP(L9,struktura!$B:$G,6,FALSE) -> 0.5 | P9: 132100588 | Q9: =IF(P9=0,0,VLOOKUP(P9,struktura!$B:$D,3,FALSE)) -> BUS CASE TOP II V2 | R9: =IF(P9=0,0,R$1/VLOOKUP(P9,struktura!$B:$F,5,FALSE)) -> 2769.2308 | S9: =VLOOKUP(P9,struktura!$B:$G,6,FALSE) -> 0.5 | T9: 132100588 | U9: =IF(T9=0,0,VLOOKUP(T9,struktura!$B:$D,3,FALSE)) -> BUS CASE TOP II V2 | V9: =IF(T9=0,0,V$1/VLOOKUP(T9,struktura!$B:$F,5,FALSE)) -> 2769.2308 | W9: =VLOOKUP(T9,struktura!$B:$G,6,FALSE) -> 0.5 | X9: 132100588 | Y9: =IF(X9=0,0,VLOOKUP(X9,struktura!$B:$D,3,FALSE)) -> BUS CASE TOP II V2 | Z9: =IF(X9=0,0,Z$1/VLOOKUP(X9,struktura!$B:$F,5,FALSE)) -> 2769.2308 | AA9: =VLOOKUP(X9,struktura!$B:$G,6,FALSE) -> 0.5 | AC9: =IF(AB9=0,0,VLOOKUP(AB9,struktura!$B:$D,3,FALSE)) -> 0 | AD9: =IF(AB9=0,0,AD$1/VLOOKUP(AB9,struktura!$B:$F,5,FALSE)) -> 0 | AE9: =VLOOKUP(AB9,struktura!$B:$G,6,FALSE) -> 0 | AG9: =IF(AF9=0,0,VLOOKUP(AF9,struktura!$B:$D,3,FALSE)) -> 0 | AH9: =IF(AF9=0,0,AH$1/VLOOKUP(AF9,struktura!$B:$F,5,FALSE)) -> 0 | AI9: =VLOOKUP(AF9,struktura!$B:$G,6,FALSE) -> 0 | AK9: =IF(AJ9=0,0,VLOOKUP(AJ9,struktura!$B:$D,3,FALSE)) -> 0 | AL9: =IF(AJ9=0,0,AL$1/VLOOKUP(AJ9,struktura!$B:$F,5,FALSE)) -> 0 | AM9: =VLOOKUP(AJ9,struktura!$B:$G,6,FALSE) -> 0 | AO9: =IF(AN9=0,0,VLOOKUP(AN9,struktura!$B:$D,3,FALSE)) -> 0 | AP9: =IF(AN9=0,0,AP$1/VLOOKUP(AN9,struktura!$B:$F,5,FALSE)) -> 0 | AQ9: =VLOOKUP(AN9,struktura!$B:$G,6,FALSE) -> 0 | AR9: 132100588 | AS9: =IF(AR9=0,0,VLOOKUP(AR9,struktura!$B:$D,3,FALSE)) -> BUS CASE TOP II V2 | AT9: =IF(AR9=0,0,AT$1/VLOOKUP(AR9,struktura!$B:$F,5,FALSE)) -> 2769.2308 | AU9: =VLOOKUP(AR9,struktura!$B:$G,6,FALSE) -> 0.5 | AV9: 132100588 | AW9: =IF(AV9=0,0,VLOOKUP(AV9,struktura!$B:$D,3,FALSE)) -> BUS CASE TOP II V2 | AX9: =IF(AV9=0,0,AX$1/VLOOKUP(AV9,struktura!$B:$F,5,FALSE)) -> 2769.2308 | AY9: =VLOOKUP(AV9,struktura!$B:$G,6,FALSE) -> 0.5 | AZ9: 132100588 | BA9: =IF(AZ9=0,0,VLOOKUP(AZ9,struktura!$B:$D,3,FALSE)) -> BUS CASE TOP II V2 | BB9: =IF(AZ9=0,0,BB$1/VLOOKUP(AZ9,struktura!$B:$F,5,FALSE)) -> 2769.2308 | BC9: =VLOOKUP(AZ9,struktura!$B:$G,6,FALSE) -> 0.5 | BD9: 132100588 | BE9: =IF(BD9=0,0,VLOOKUP(BD9,struktura!$B:$D,3,FALSE)) -> BUS CASE TOP II V2 | BF9: =IF(BD9=0,0,BF$1/VLOOKUP(BD9,struktura!$B:$F,5,FALSE)) -> 2769.2308 | BG9: =VLOOKUP(BD9,struktura!$B:$G,6,FALSE) -> 0.5 | BH9: 132100588 | BI9: =IF(BH9=0,0,VLOOKUP(BH9,struktura!$B:$D,3,FALSE)) -> BUS CASE TOP II V2 | BJ9: =IF(BH9=0,0,BJ$1/VLOOKUP(BH9,struktura!$B:$F,5,FALSE)) -> 2769.2308 | BK9: =VLOOKUP(BH9,struktura!$B:$G,6,FALSE) -> 0.5 | BM9: =IF(BL9=0,0,VLOOKUP(BL9,struktura!$B:$D,3,FALSE)) -> 0 | BN9: =IF(BL9=0,0,BN$1/VLOOKUP(BL9,struktura!$B:$F,5,FALSE)) -> 0 | BO9: =VLOOKUP(BL9,struktura!$B:$G,6,FALSE) -> 0 | BQ9: =IF(BP9=0,0,VLOOKUP(BP9,struktura!$B:$D,3,FALSE)) -> 0 | BR9: =IF(BP9=0,0,BR$1/VLOOKUP(BP9,struktura!$B:$F,5,FALSE)) -> 0 | BS9: =VLOOKUP(BP9,struktura!$B:$G,6,FALSE) -> 0 | BU9: =IF(BT9=0,0,VLOOKUP(BT9,struktura!$B:$D,3,FALSE)) -> 0 | BV9: =IF(BT9=0,0,BV$1/VLOOKUP(BT9,struktura!$B:$F,5,FALSE)) -> 0 | BW9: =VLOOKUP(BT9,struktura!$B:$G,6,FALSE) -> 0 | BY9: =IF(BX9=0,0,VLOOKUP(BX9,struktura!$B:$D,3,FALSE)) -> 0 | BZ9: =IF(BX9=0,0,BZ$1/VLOOKUP(BX9,struktura!$B:$F,5,FALSE)) -> 0 | CA9: =VLOOKUP(BX9,struktura!$B:$G,6,FALSE) -> 0 | CC9: =IF(CB9=0,0,VLOOKUP(CB9,struktura!$B:$D,3,FALSE)) -> 0 | CD9: =IF(CB9=0,0,CD$1/VLOOKUP(CB9,struktura!$B:$F,5,FALSE)) -> 0 | CE9: =VLOOKUP(CB9,struktura!$B:$G,6,FALSE) -> 0 | CG9: =IF(CF9=0,0,VLOOKUP(CF9,struktura!$B:$D,3,FALSE)) -> 0 | CH9: =IF(CF9=0,0,CH$1/VLOOKUP(CF9,struktura!$B:$F,5,FALSE)) -> 0 | CI9: =VLOOKUP(CF9,struktura!$B:$G,6,FALSE) -> 0 | CK9: =IF(CJ9=0,0,VLOOKUP(CJ9,struktura!$B:$D,3,FALSE)) -> 0 | CL9: =IF(CJ9=0,0,CL$1/VLOOKUP(CJ9,struktura!$B:$F,5,FALSE)) -> 0 | CM9: =VLOOKUP(CJ9,struktura!$B:$G,6,FALSE) -> 0 | CO9: =IF(CN9=0,0,VLOOKUP(CN9,struktura!$B:$D,3,FALSE)) -> 0 | CP9: =IF(CN9=0,0,CP$1/VLOOKUP(CN9,struktura!$B:$F,5,FALSE)) -> 0 | CQ9: =VLOOKUP(CN9,struktura!$B:$G,6,FALSE) -> 0 | CS9: =IF(CR9=0,0,VLOOKUP(CR9,struktura!$B:$D,3,FALSE)) -> 0 | CT9: =IF(CR9=0,0,CT$1/VLOOKUP(CR9,struktura!$B:$F,5,FALSE)) -> 0 | CU9: =VLOOKUP(CR9,struktura!$B:$G,6,FALSE) -> 0 | CW9: =IF(CV9=0,0,VLOOKUP(CV9,struktura!$B:$D,3,FALSE)) -> 0 | CX9: =IF(CV9=0,0,CX$1/VLOOKUP(CV9,struktura!$B:$F,5,FALSE)) -> 0 | CY9: =VLOOKUP(CV9,struktura!$B:$G,6,FALSE) -> 0 | DE9: =IF(DD9=0,0,VLOOKUP(DD9,struktura!$B:$D,3,FALSE)) -> 0 | DF9: =IF(DD9=0,0,DF$1/VLOOKUP(DD9,struktura!$B:$F,5,FALSE)) -> 0 | DG9: =VLOOKUP(DD9,struktura!$B:$G,6,FALSE) -> 0 | DI9: =IF(DH9=0,0,VLOOKUP(DH9,struktura!$B:$D,3,FALSE)) -> 0 | DJ9: =IF(DH9=0,0,DJ$1/VLOOKUP(DH9,struktura!$B:$F,5,FALSE)) -> 0 | DK9: =VLOOKUP(DH9,struktura!$B:$G,6,FALSE) -> 0 | DM9: =IF(DL9=0,0,VLOOKUP(DL9,struktura!$B:$D,3,FALSE)) -> 0 | DN9: =IF(DL9=0,0,DN$1/VLOOKUP(DL9,struktura!$B:$F,5,FALSE)) -> 0 | DO9: =VLOOKUP(DL9,struktura!$B:$G,6,FALSE) -> 0 | DQ9: =IF(DP9=0,0,VLOOKUP(DP9,struktura!$B:$D,3,FALSE)) -> 0 | DR9: =IF(DP9=0,0,DR$1/VLOOKUP(DP9,struktura!$B:$F,5,FALSE)) -> 0 | DS9: =VLOOKUP(DP9,struktura!$B:$G,6,FALSE) -> 0
H10: nadaljevanje | AB10: 5S delavnica - 2 dni | AR10: P250810692 menjava orodja
B11: 2 | C11: KM 420 R | E11: =IF(D11=0,"0",VLOOKUP(D11,struktura!$B:$D,3,FALSE)) -> 0 | F11: =IF(D11=0,"",24/VLOOKUP(D11,struktura!$B:$F,5,FALSE)) | G11: =VLOOKUP(D11,struktura!$B:$G,6,FALSE) -> 0 | I11: 0 | J11: 0 | K11: 0 | M11: =IF(L11=0,0,VLOOKUP(L11,struktura!$B:$D,3,FALSE)) -> 0 | N11: =IF(L11=0,0,N$1/VLOOKUP(L11,struktura!$B:$F,5,FALSE)) -> 0 | O11: =VLOOKUP(L11,struktura!$B:$G,6,FALSE) -> 0 | Q11: =IF(P11=0,0,VLOOKUP(P11,struktura!$B:$D,3,FALSE)) -> 0 | R11: =IF(P11=0,0,R$1/VLOOKUP(P11,struktura!$B:$F,5,FALSE)) -> 0 | S11: =VLOOKUP(P11,struktura!$B:$G,6,FALSE) -> 0 | U11: =IF(T11=0,0,VLOOKUP(T11,struktura!$B:$D,3,FALSE)) -> 0 | V11: =IF(T11=0,0,V$1/VLOOKUP(T11,struktura!$B:$F,5,FALSE)) -> 0 | W11: =VLOOKUP(T11,struktura!$B:$G,6,FALSE) -> 0 | Y11: =IF(X11=0,0,VLOOKUP(X11,struktura!$B:$D,3,FALSE)) -> 0 | Z11: =IF(X11=0,0,Z$1/VLOOKUP(X11,struktura!$B:$F,5,FALSE)) -> 0 | AA11: =VLOOKUP(X11,struktura!$B:$G,6,FALSE) -> 0 | AC11: =IF(AB11=0,0,VLOOKUP(AB11,struktura!$B:$D,3,FALSE)) -> 0 | AD11: =IF(AB11=0,0,AD$1/VLOOKUP(AB11,struktura!$B:$F,5,FALSE)) -> 0 | AE11: =VLOOKUP(AB11,struktura!$B:$G,6,FALSE) -> 0 | AG11: =IF(AF11=0,0,VLOOKUP(AF11,struktura!$B:$D,3,FALSE)) -> 0 | AH11: =IF(AF11=0,0,AH$1/VLOOKUP(AF11,struktura!$B:$F,5,FALSE)) -> 0 | AI11: =VLOOKUP(AF11,struktura!$B:$G,6,FALSE) -> 0 | AK11: =IF(AJ11=0,0,VLOOKUP(AJ11,struktura!$B:$D,3,FALSE)) -> 0 | AL11: =IF(AJ11=0,0,AL$1/VLOOKUP(AJ11,struktura!$B:$F,5,FALSE)) -> 0 | AM11: =VLOOKUP(AJ11,struktura!$B:$G,6,FALSE) -> 0 | AO11: =IF(AN11=0,0,VLOOKUP(AN11,struktura!$B:$D,3,FALSE)) -> 0 | AP11: =IF(AN11=0,0,AP$1/VLOOKUP(AN11,struktura!$B:$F,5,FALSE)) -> 0 | AQ11: =VLOOKUP(AN11,struktura!$B:$G,6,FALSE) -> 0 | AS11: =IF(AR11=0,0,VLOOKUP(AR11,struktura!$B:$D,3,FALSE)) -> 0 | AT11: =IF(AR11=0,0,AT$1/VLOOKUP(AR11,struktura!$B:$F,5,FALSE)) -> 0 | AU11: =VLOOKUP(AR11,struktura!$B:$G,6,FALSE) -> 0 | AW11: =IF(AV11=0,0,VLOOKUP(AV11,struktura!$B:$D,3,FALSE)) -> 0 | AX11: =IF(AV11=0,0,AX$1/VLOOKUP(AV11,struktura!$B:$F,5,FALSE)) -> 0 | AY11: =VLOOKUP(AV11,struktura!$B:$G,6,FALSE) -> 0 | BA11: =IF(AZ11=0,0,VLOOKUP(AZ11,struktura!$B:$D,3,FALSE)) -> 0 | BB11: =IF(AZ11=0,0,BB$1/VLOOKUP(AZ11,struktura!$B:$F,5,FALSE)) -> 0 | BC11: =VLOOKUP(AZ11,struktura!$B:$G,6,FALSE) -> 0 | BE11: =IF(BD11=0,0,VLOOKUP(BD11,struktura!$B:$D,3,FALSE)) -> 0 | BF11: =IF(BD11=0,0,BF$1/VLOOKUP(BD11,struktura!$B:$F,5,FALSE)) -> 0 | BG11: =VLOOKUP(BD11,struktura!$B:$G,6,FALSE) -> 0 | BI11: =IF(BH11=0,0,VLOOKUP(BH11,struktura!$B:$D,3,FALSE)) -> 0 | BJ11: =IF(BH11=0,0,BJ$1/VLOOKUP(BH11,struktura!$B:$F,5,FALSE)) -> 0 | BK11: =VLOOKUP(BH11,struktura!$B:$G,6,FALSE) -> 0 | BM11: =IF(BL11=0,0,VLOOKUP(BL11,struktura!$B:$D,3,FALSE)) -> 0 | BN11: =IF(BL11=0,0,BN$1/VLOOKUP(BL11,struktura!$B:$F,5,FALSE)) -> 0 | BO11: =VLOOKUP(BL11,struktura!$B:$G,6,FALSE) -> 0 | BQ11: =IF(BP11=0,0,VLOOKUP(BP11,struktura!$B:$D,3,FALSE)) -> 0 | BR11: =IF(BP11=0,0,BR$1/VLOOKUP(BP11,struktura!$B:$F,5,FALSE)) -> 0 | BS11: =VLOOKUP(BP11,struktura!$B:$G,6,FALSE) -> 0 | BU11: =IF(BT11=0,0,VLOOKUP(BT11,struktura!$B:$D,3,FALSE)) -> 0 | BV11: =IF(BT11=0,0,BV$1/VLOOKUP(BT11,struktura!$B:$F,5,FALSE)) -> 0 | BW11: =VLOOKUP(BT11,struktura!$B:$G,6,FALSE) -> 0 | BY11: =IF(BX11=0,0,VLOOKUP(BX11,struktura!$B:$D,3,FALSE)) -> 0 | BZ11: =IF(BX11=0,0,BZ$1/VLOOKUP(BX11,struktura!$B:$F,5,FALSE)) -> 0 | CA11: =VLOOKUP(BX11,struktura!$B:$G,6,FALSE) -> 0 | CC11: =IF(CB11=0,0,VLOOKUP(CB11,struktura!$B:$D,3,FALSE)) -> 0 | CD11: =IF(CB11=0,0,CD$1/VLOOKUP(CB11,struktura!$B:$F,5,FALSE)) -> 0 | CE11: =VLOOKUP(CB11,struktura!$B:$G,6,FALSE) -> 0 | CG11: =IF(CF11=0,0,VLOOKUP(CF11,struktura!$B:$D,3,FALSE)) -> 0 | CH11: =IF(CF11=0,0,CH$1/VLOOKUP(CF11,struktura!$B:$F,5,FALSE)) -> 0 | CI11: =VLOOKUP(CF11,struktura!$B:$G,6,FALSE) -> 0 | CK11: =IF(CJ11=0,0,VLOOKUP(CJ11,struktura!$B:$D,3,FALSE)) -> 0 | CL11: =IF(CJ11=0,0,CL$1/VLOOKUP(CJ11,struktura!$B:$F,5,FALSE)) -> 0 | CM11: =VLOOKUP(CJ11,struktura!$B:$G,6,FALSE) -> 0 | CO11: =IF(CN11=0,0,VLOOKUP(CN11,struktura!$B:$D,3,FALSE)) -> 0 | CP11: =IF(CN11=0,0,CP$1/VLOOKUP(CN11,struktura!$B:$F,5,FALSE)) -> 0 | CQ11: =VLOOKUP(CN11,struktura!$B:$G,6,FALSE) -> 0 | CS11: =IF(CR11=0,0,VLOOKUP(CR11,struktura!$B:$D,3,FALSE)) -> 0 | CT11: =IF(CR11=0,0,CT$1/VLOOKUP(CR11,struktura!$B:$F,5,FALSE)) -> 0 | CU11: =VLOOKUP(CR11,struktura!$B:$G,6,FALSE) -> 0 | CW11: =IF(CV11=0,0,VLOOKUP(CV11,struktura!$B:$D,3,FALSE)) -> 0 | CX11: =IF(CV11=0,0,CX$1/VLOOKUP(CV11,struktura!$B:$F,5,FALSE)) -> 0 | CY11: =VLOOKUP(CV11,struktura!$B:$G,6,FALSE) -> 0 | DE11: =IF(DD11=0,0,VLOOKUP(DD11,struktura!$B:$D,3,FALSE)) -> 0 | DF11: =IF(DD11=0,0,DF$1/VLOOKUP(DD11,struktura!$B:$F,5,FALSE)) -> 0 | DG11: =VLOOKUP(DD11,struktura!$B:$G,6,FALSE) -> 0 | DI11: =IF(DH11=0,0,VLOOKUP(DH11,struktura!$B:$D,3,FALSE)) -> 0 | DJ11: =IF(DH11=0,0,DJ$1/VLOOKUP(DH11,struktura!$B:$F,5,FALSE)) -> 0 | DK11: =VLOOKUP(DH11,struktura!$B:$G,6,FALSE) -> 0 | DM11: =IF(DL11=0,0,VLOOKUP(DL11,struktura!$B:$D,3,FALSE)) -> 0 | DN11: =IF(DL11=0,0,DN$1/VLOOKUP(DL11,struktura!$B:$F,5,FALSE)) -> 0 | DO11: =VLOOKUP(DL11,struktura!$B:$G,6,FALSE) -> 0 | DQ11: =IF(DP11=0,0,VLOOKUP(DP11,struktura!$B:$D,3,FALSE)) -> 0 | DR11: =IF(DP11=0,0,DR$1/VLOOKUP(DP11,struktura!$B:$F,5,FALSE)) -> 0 | DS11: =VLOOKUP(DP11,struktura!$B:$G,6,FALSE) -> 0
AB12: 5S delavnica - 2 dni
B13: 17 | C13: KM420 R | E13: =IF(D13=0,"0",VLOOKUP(D13,struktura!$B:$D,3,FALSE)) -> 0 | F13: =IF(D13=0,"",24/VLOOKUP(D13,struktura!$B:$F,5,FALSE)) | G13: =VLOOKUP(D13,struktura!$B:$G,6,FALSE) -> 0 | H13: 200100039 | I13: Vodilnik zraka vrat BIO2 | J13: 4020 | K13: 0.25 | L13: 200100039 | M13: =IF(L13=0,0,VLOOKUP(L13,struktura!$B:$D,3,FALSE)) -> Vodilnik zraka vrat BIO2 | N13: =IF(L13=0,0,N$1/VLOOKUP(L13,struktura!$B:$F,5,FALSE)) -> 4020 | O13: =VLOOKUP(L13,struktura!$B:$G,6,FALSE) -> 0.25 | P13: 200100039 | Q13: =IF(P13=0,0,VLOOKUP(P13,struktura!$B:$D,3,FALSE)) -> Vodilnik zraka vrat BIO2 | R13: =IF(P13=0,0,R$1/VLOOKUP(P13,struktura!$B:$F,5,FALSE)) -> 4020 | S13: =VLOOKUP(P13,struktura!$B:$G,6,FALSE) -> 0.25 | T13: 200100039 | U13: =IF(T13=0,0,VLOOKUP(T13,struktura!$B:$D,3,FALSE)) -> Vodilnik zraka vrat BIO2 | V13: =IF(T13=0,0,V$1/VLOOKUP(T13,struktura!$B:$F,5,FALSE)) -> 4020 | W13: =VLOOKUP(T13,struktura!$B:$G,6,FALSE) -> 0.25 | X13: 200100039 | Y13: =IF(X13=0,0,VLOOKUP(X13,struktura!$B:$D,3,FALSE)) -> Vodilnik zraka vrat BIO2 | Z13: =IF(X13=0,0,Z$1/VLOOKUP(X13,struktura!$B:$F,5,FALSE)) -> 4020 | AA13: =VLOOKUP(X13,struktura!$B:$G,6,FALSE) -> 0.25 | AB13: 200100039 | AC13: =IF(AB13=0,0,VLOOKUP(AB13,struktura!$B:$D,3,FALSE)) -> Vodilnik zraka vrat BIO2 | AD13: =IF(AB13=0,0,AD$1/VLOOKUP(AB13,struktura!$B:$F,5,FALSE)) -> 4020 | AE13: =VLOOKUP(AB13,struktura!$B:$G,6,FALSE) -> 0.25 | AF13: 200100039 | AG13: =IF(AF13=0,0,VLOOKUP(AF13,struktura!$B:$D,3,FALSE)) -> Vodilnik zraka vrat BIO2 | AH13: =IF(AF13=0,0,AH$1/VLOOKUP(AF13,struktura!$B:$F,5,FALSE)) -> 4020 | AI13: =VLOOKUP(AF13,struktura!$B:$G,6,FALSE) -> 0.25 | AJ13: 200100039 | AK13: =IF(AJ13=0,0,VLOOKUP(AJ13,struktura!$B:$D,3,FALSE)) -> Vodilnik zraka vrat BIO2 | AL13: =IF(AJ13=0,0,AL$1/VLOOKUP(AJ13,struktura!$B:$F,5,FALSE)) -> 4020 | AM13: =VLOOKUP(AJ13,struktura!$B:$G,6,FALSE) -> 0.25 | AN13: 200100039 | AO13: =IF(AN13=0,0,VLOOKUP(AN13,struktura!$B:$D,3,FALSE)) -> Vodilnik zraka vrat BIO2 | AP13: =IF(AN13=0,0,AP$1/VLOOKUP(AN13,struktura!$B:$F,5,FALSE)) -> 4020 | AQ13: =VLOOKUP(AN13,struktura!$B:$G,6,FALSE) -> 0.25 | AR13: 200100039 | AS13: =IF(AR13=0,0,VLOOKUP(AR13,struktura!$B:$D,3,FALSE)) -> Vodilnik zraka vrat BIO2 | AT13: =IF(AR13=0,0,AT$1/VLOOKUP(AR13,struktura!$B:$F,5,FALSE)) -> 4020 | AU13: =VLOOKUP(AR13,struktura!$B:$G,6,FALSE) -> 0.25 | AV13: 200100039 | AW13: =IF(AV13=0,0,VLOOKUP(AV13,struktura!$B:$D,3,FALSE)) -> Vodilnik zraka vrat BIO2 | AX13: =IF(AV13=0,0,AX$1/VLOOKUP(AV13,struktura!$B:$F,5,FALSE)) -> 4020 | AY13: =VLOOKUP(AV13,struktura!$B:$G,6,FALSE) -> 0.25 | AZ13: 200100039 | BA13: =IF(AZ13=0,0,VLOOKUP(AZ13,struktura!$B:$D,3,FALSE)) -> Vodilnik zraka vrat BIO2 | BB13: =IF(AZ13=0,0,BB$1/VLOOKUP(AZ13,struktura!$B:$F,5,FALSE)) -> 4020 | BC13: =VLOOKUP(AZ13,struktura!$B:$G,6,FALSE) -> 0.25 | BD13: 200100039 | BE13: =IF(BD13=0,0,VLOOKUP(BD13,struktura!$B:$D,3,FALSE)) -> Vodilnik zraka vrat BIO2 | BF13: =IF(BD13=0,0,BF$1/VLOOKUP(BD13,struktura!$B:$F,5,FALSE)) -> 4020 | BG13: =VLOOKUP(BD13,struktura!$B:$G,6,FALSE) -> 0.25 | BH13: 200100039 | BI13: =IF(BH13=0,0,VLOOKUP(BH13,struktura!$B:$D,3,FALSE)) -> Vodilnik zraka vrat BIO2 | BJ13: =IF(BH13=0,0,BJ$1/VLOOKUP(BH13,struktura!$B:$F,5,FALSE)) -> 4020 | BK13: =VLOOKUP(BH13,struktura!$B:$G,6,FALSE) -> 0.25 | BM13: =IF(BL13=0,0,VLOOKUP(BL13,struktura!$B:$D,3,FALSE)) -> 0 | BN13: =IF(BL13=0,0,BN$1/VLOOKUP(BL13,struktura!$B:$F,5,FALSE)) -> 0 | BO13: =VLOOKUP(BL13,struktura!$B:$G,6,FALSE) -> 0 | BQ13: =IF(BP13=0,0,VLOOKUP(BP13,struktura!$B:$D,3,FALSE)) -> 0 | BR13: =IF(BP13=0,0,BR$1/VLOOKUP(BP13,struktura!$B:$F,5,FALSE)) -> 0 | BS13: =VLOOKUP(BP13,struktura!$B:$G,6,FALSE) -> 0 | BU13: =IF(BT13=0,0,VLOOKUP(BT13,struktura!$B:$D,3,FALSE)) -> 0 | BV13: =IF(BT13=0,0,BV$1/VLOOKUP(BT13,struktura!$B:$F,5,FALSE)) -> 0 | BW13: =VLOOKUP(BT13,struktura!$B:$G,6,FALSE) -> 0 | BY13: =IF(BX13=0,0,VLOOKUP(BX13,struktura!$B:$D,3,FALSE)) -> 0 | BZ13: =IF(BX13=0,0,BZ$1/VLOOKUP(BX13,struktura!$B:$F,5,FALSE)) -> 0 | CA13: =VLOOKUP(BX13,struktura!$B:$G,6,FALSE) -> 0 | CC13: =IF(CB13=0,0,VLOOKUP(CB13,struktura!$B:$D,3,FALSE)) -> 0 | CD13: =IF(CB13=0,0,CD$1/VLOOKUP(CB13,struktura!$B:$F,5,FALSE)) -> 0 | CE13: =VLOOKUP(CB13,struktura!$B:$G,6,FALSE) -> 0 | CG13: =IF(CF13=0,0,VLOOKUP(CF13,struktura!$B:$D,3,FALSE)) -> 0 | CH13: =IF(CF13=0,0,CH$1/VLOOKUP(CF13,struktura!$B:$F,5,FALSE)) -> 0 | CI13: =VLOOKUP(CF13,struktura!$B:$G,6,FALSE) -> 0 | CK13: =IF(CJ13=0,0,VLOOKUP(CJ13,struktura!$B:$D,3,FALSE)) -> 0 | CL13: =IF(CJ13=0,0,CL$1/VLOOKUP(CJ13,struktura!$B:$F,5,FALSE)) -> 0 | CM13: =VLOOKUP(CJ13,struktura!$B:$G,6,FALSE) -> 0 | CO13: =IF(CN13=0,0,VLOOKUP(CN13,struktura!$B:$D,3,FALSE)) -> 0 | CP13: =IF(CN13=0,0,CP$1/VLOOKUP(CN13,struktura!$B:$F,5,FALSE)) -> 0 | CQ13: =VLOOKUP(CN13,struktura!$B:$G,6,FALSE) -> 0 | CS13: =IF(CR13=0,0,VLOOKUP(CR13,struktura!$B:$D,3,FALSE)) -> 0 | CT13: =IF(CR13=0,0,CT$1/VLOOKUP(CR13,struktura!$B:$F,5,FALSE)) -> 0 | CU13: =VLOOKUP(CR13,struktura!$B:$G,6,FALSE) -> 0 | CW13: =IF(CV13=0,0,VLOOKUP(CV13,struktura!$B:$D,3,FALSE)) -> 0 | CX13: =IF(CV13=0,0,CX$1/VLOOKUP(CV13,struktura!$B:$F,5,FALSE)) -> 0 | CY13: =VLOOKUP(CV13,struktura!$B:$G,6,FALSE) -> 0 | DE13: =IF(DD13=0,0,VLOOKUP(DD13,struktura!$B:$D,3,FALSE)) -> 0 | DF13: =IF(DD13=0,0,DF$1/VLOOKUP(DD13,struktura!$B:$F,5,FALSE)) -> 0 | DG13: =VLOOKUP(DD13,struktura!$B:$G,6,FALSE) -> 0 | DI13: =IF(DH13=0,0,VLOOKUP(DH13,struktura!$B:$D,3,FALSE)) -> 0 | DJ13: =IF(DH13=0,0,DJ$1/VLOOKUP(DH13,struktura!$B:$F,5,FALSE)) -> 0 | DK13: =VLOOKUP(DH13,struktura!$B:$G,6,FALSE) -> 0 | DM13: =IF(DL13=0,0,VLOOKUP(DL13,struktura!$B:$D,3,FALSE)) -> 0 | DN13: =IF(DL13=0,0,DN$1/VLOOKUP(DL13,struktura!$B:$F,5,FALSE)) -> 0 | DO13: =VLOOKUP(DL13,struktura!$B:$G,6,FALSE) -> 0 | DQ13: =IF(DP13=0,0,VLOOKUP(DP13,struktura!$B:$D,3,FALSE)) -> 0 | DR13: =IF(DP13=0,0,DR$1/VLOOKUP(DP13,struktura!$B:$F,5,FALSE)) -> 0 | DS13: =VLOOKUP(DP13,struktura!$B:$G,6,FALSE) -> 0
T14: servis orodja | X14: nalog zaključit | AB14: P251008920 nalog za 48 ur - 2 dni - sistemski test | AJ14: P251008921, redna serija
B15: 3 | C15: EN 400 R | E15: =IF(D15=0,"0",VLOOKUP(D15,struktura!$B:$D,3,FALSE)) -> 0 | F15: =IF(D15=0,"",24/VLOOKUP(D15,struktura!$B:$F,5,FALSE)) | G15: =VLOOKUP(D15,struktura!$B:$G,6,FALSE) -> 0 | H15: 132100014 | I15: OHIŠJE ROKE ZGORNJE K16_x000D_ (belo) | J15: 2880 | K15: 0.5 | L15: 132100014 | M15: =IF(L15=0,0,VLOOKUP(L15,struktura!$B:$D,3,FALSE)) -> OHIŠJE ROKE ZGORNJE K16 (belo) | N15: =IF(L15=0,0,N$1/VLOOKUP(L15,struktura!$B:$F,5,FALSE)) -> 2880 | O15: =VLOOKUP(L15,struktura!$B:$G,6,FALSE) -> 0.5 | P15: 132100014 | Q15: =IF(P15=0,0,VLOOKUP(P15,struktura!$B:$D,3,FALSE)) -> OHIŠJE ROKE ZGORNJE K16 (belo) | R15: =IF(P15=0,0,R$1/VLOOKUP(P15,struktura!$B:$F,5,FALSE)) -> 2880 | S15: =VLOOKUP(P15,struktura!$B:$G,6,FALSE) -> 0.5 | U15: =IF(T15=0,0,VLOOKUP(T15,struktura!$B:$D,3,FALSE)) -> 0 | V15: =IF(T15=0,0,V$1/VLOOKUP(T15,struktura!$B:$F,5,FALSE)) -> 0 | W15: =VLOOKUP(T15,struktura!$B:$G,6,FALSE) -> 0 | Y15: =IF(X15=0,0,VLOOKUP(X15,struktura!$B:$D,3,FALSE)) -> 0 | Z15: =IF(X15=0,0,Z$1/VLOOKUP(X15,struktura!$B:$F,5,FALSE)) -> 0 | AA15: =VLOOKUP(X15,struktura!$B:$G,6,FALSE) -> 0 | AB15: 132300624 | AC15: =IF(AB15=0,0,VLOOKUP(AB15,struktura!$B:$D,3,FALSE)) -> FRONT PANEL TOP 450H White vodilo svetlobe odprto | AD15: =IF(AB15=0,0,AD$1/VLOOKUP(AB15,struktura!$B:$F,5,FALSE)) -> 1728 | AE15: =VLOOKUP(AB15,struktura!$B:$G,6,FALSE) -> 1 | AF15: 132300620 | AG15: =IF(AF15=0,0,VLOOKUP(AF15,struktura!$B:$D,3,FALSE)) -> FRONT PANEL TOP 450H vodilo svetlobe odprto | AH15: =IF(AF15=0,0,AH$1/VLOOKUP(AF15,struktura!$B:$F,5,FALSE)) -> 1728 | AI15: =VLOOKUP(AF15,struktura!$B:$G,6,FALSE) -> 1 | AJ15: 132300620 | AK15: =IF(AJ15=0,0,VLOOKUP(AJ15,struktura!$B:$D,3,FALSE)) -> FRONT PANEL TOP 450H vodilo svetlobe odprto | AL15: =IF(AJ15=0,0,AL$1/VLOOKUP(AJ15,struktura!$B:$F,5,FALSE)) -> 1728 | AM15: =VLOOKUP(AJ15,struktura!$B:$G,6,FALSE) -> 1 | AN15: 132300619 | AO15: =IF(AN15=0,0,VLOOKUP(AN15,struktura!$B:$D,3,FALSE)) -> FRONT PANEL TOP 450 black | AP15: =IF(AN15=0,0,AP$1/VLOOKUP(AN15,struktura!$B:$F,5,FALSE)) -> 1728 | AQ15: =VLOOKUP(AN15,struktura!$B:$G,6,FALSE) -> 1 | AR15: 132110061 | AS15: =IF(AR15=0,0,VLOOKUP(AR15,struktura!$B:$D,3,FALSE)) -> PLOŠČA SPREDNJA ZGORAJ S4 RNA sur zaprto vodilo svetlobe | AT15: =IF(AR15=0,0,AT$1/VLOOKUP(AR15,struktura!$B:$F,5,FALSE)) -> 1500 | AU15: =VLOOKUP(AR15,struktura!$B:$G,6,FALSE) -> 1 | AV15: t | AW15: =IF(AV15=0,0,VLOOKUP(AV15,struktura!$B:$D,3,FALSE)) -> rezervirano za tehnologijo | AX15: =IF(AV15=0,0,AX$1/VLOOKUP(AV15,struktura!$B:$F,5,FALSE)) -> 24 | AY15: =VLOOKUP(AV15,struktura!$B:$G,6,FALSE) -> 0 | BA15: =IF(AZ15=0,0,VLOOKUP(AZ15,struktura!$B:$D,3,FALSE)) -> 0 | BB15: =IF(AZ15=0,0,BB$1/VLOOKUP(AZ15,struktura!$B:$F,5,FALSE)) -> 0 | BC15: =VLOOKUP(AZ15,struktura!$B:$G,6,FALSE) -> 0 | BE15: =IF(BD15=0,0,VLOOKUP(BD15,struktura!$B:$D,3,FALSE)) -> 0 | BF15: =IF(BD15=0,0,BF$1/VLOOKUP(BD15,struktura!$B:$F,5,FALSE)) -> 0 | BG15: =VLOOKUP(BD15,struktura!$B:$G,6,FALSE) -> 0 | BI15: =IF(BH15=0,0,VLOOKUP(BH15,struktura!$B:$D,3,FALSE)) -> 0 | BJ15: =IF(BH15=0,0,BJ$1/VLOOKUP(BH15,struktura!$B:$F,5,FALSE)) -> 0 | BK15: =VLOOKUP(BH15,struktura!$B:$G,6,FALSE) -> 0 | BL15: 132100013 | BM15: =IF(BL15=0,0,VLOOKUP(BL15,struktura!$B:$D,3,FALSE)) -> OHIŠJE ROKE SPODNJE K16 bela | BN15: =IF(BL15=0,0,BN$1/VLOOKUP(BL15,struktura!$B:$F,5,FALSE)) -> 3456 | BO15: =VLOOKUP(BL15,struktura!$B:$G,6,FALSE) -> 0.5 | BP15: 132100013 | BQ15: =IF(BP15=0,0,VLOOKUP(BP15,struktura!$B:$D,3,FALSE)) -> OHIŠJE ROKE SPODNJE K16 bela | BR15: =IF(BP15=0,0,BR$1/VLOOKUP(BP15,struktura!$B:$F,5,FALSE)) -> 3456 | BS15: =VLOOKUP(BP15,struktura!$B:$G,6,FALSE) -> 0.5 | BT15: 132100013 | BU15: =IF(BT15=0,0,VLOOKUP(BT15,struktura!$B:$D,3,FALSE)) -> OHIŠJE ROKE SPODNJE K16 bela | BV15: =IF(BT15=0,0,BV$1/VLOOKUP(BT15,struktura!$B:$F,5,FALSE)) -> 3456 | BW15: =VLOOKUP(BT15,struktura!$B:$G,6,FALSE) -> 0.5 | BX15: 132100013 | BY15: =IF(BX15=0,0,VLOOKUP(BX15,struktura!$B:$D,3,FALSE)) -> OHIŠJE ROKE SPODNJE K16 bela | BZ15: =IF(BX15=0,0,BZ$1/VLOOKUP(BX15,struktura!$B:$F,5,FALSE)) -> 3456 | CA15: =VLOOKUP(BX15,struktura!$B:$G,6,FALSE) -> 0.5 | CB15: 132100014 | CC15: =IF(CB15=0,0,VLOOKUP(CB15,struktura!$B:$D,3,FALSE)) -> OHIŠJE ROKE ZGORNJE K16 (belo) | CD15: =IF(CB15=0,0,CD$1/VLOOKUP(CB15,struktura!$B:$F,5,FALSE)) -> 2880 | CE15: =VLOOKUP(CB15,struktura!$B:$G,6,FALSE) -> 0.5 | CF15: 132100014 | CG15: =IF(CF15=0,0,VLOOKUP(CF15,struktura!$B:$D,3,FALSE)) -> OHIŠJE ROKE ZGORNJE K16 (belo) | CH15: =IF(CF15=0,0,CH$1/VLOOKUP(CF15,struktura!$B:$F,5,FALSE)) -> 2880 | CI15: =VLOOKUP(CF15,struktura!$B:$G,6,FALSE) -> 0.5 | CJ15: 132100014 | CK15: =IF(CJ15=0,0,VLOOKUP(CJ15,struktura!$B:$D,3,FALSE)) -> OHIŠJE ROKE ZGORNJE K16 (belo) | CL15: =IF(CJ15=0,0,CL$1/VLOOKUP(CJ15,struktura!$B:$F,5,FALSE)) -> 2880 | CM15: =VLOOKUP(CJ15,struktura!$B:$G,6,FALSE) -> 0.5 | CN15: 132100014 | CO15: =IF(CN15=0,0,VLOOKUP(CN15,struktura!$B:$D,3,FALSE)) -> OHIŠJE ROKE ZGORNJE K16 (belo) | CP15: =IF(CN15=0,0,CP$1/VLOOKUP(CN15,struktura!$B:$F,5,FALSE)) -> 2880 | CQ15: =VLOOKUP(CN15,struktura!$B:$G,6,FALSE) -> 0.5 | CS15: =IF(CR15=0,0,VLOOKUP(CR15,struktura!$B:$D,3,FALSE)) -> 0 | CT15: =IF(CR15=0,0,CT$1/VLOOKUP(CR15,struktura!$B:$F,5,FALSE)) -> 0 | CU15: =VLOOKUP(CR15,struktura!$B:$G,6,FALSE) -> 0 | CW15: =IF(CV15=0,0,VLOOKUP(CV15,struktura!$B:$D,3,FALSE)) -> 0 | CX15: =IF(CV15=0,0,CX$1/VLOOKUP(CV15,struktura!$B:$F,5,FALSE)) -> 0 | CY15: =VLOOKUP(CV15,struktura!$B:$G,6,FALSE) -> 0 | DE15: =IF(DD15=0,0,VLOOKUP(DD15,struktura!$B:$D,3,FALSE)) -> 0 | DF15: =IF(DD15=0,0,DF$1/VLOOKUP(DD15,struktura!$B:$F,5,FALSE)) -> 0 | DG15: =VLOOKUP(DD15,struktura!$B:$G,6,FALSE) -> 0 | DI15: =IF(DH15=0,0,VLOOKUP(DH15,struktura!$B:$D,3,FALSE)) -> 0 | DJ15: =IF(DH15=0,0,DJ$1/VLOOKUP(DH15,struktura!$B:$F,5,FALSE)) -> 0 | DK15: =VLOOKUP(DH15,struktura!$B:$G,6,FALSE) -> 0 | DM15: =IF(DL15=0,0,VLOOKUP(DL15,struktura!$B:$D,3,FALSE)) -> 0 | DN15: =IF(DL15=0,0,DN$1/VLOOKUP(DL15,struktura!$B:$F,5,FALSE)) -> 0 | DO15: =VLOOKUP(DL15,struktura!$B:$G,6,FALSE) -> 0 | DQ15: =IF(DP15=0,0,VLOOKUP(DP15,struktura!$B:$D,3,FALSE)) -> 0 | DR15: =IF(DP15=0,0,DR$1/VLOOKUP(DP15,struktura!$B:$F,5,FALSE)) -> 0 | DS15: =VLOOKUP(DP15,struktura!$B:$G,6,FALSE) -> 0
AB16: P250809847 800kos, sledi črna | AF16: P250909830 serija do 2.800 kos | AN16: MINI100702 serija 2000 | AR16: P250810974- test orodja po popravilu do 500 kos | AV16: 30kos V2500171 alternativni material | CB16: serija 4 dni? 5/8
B17: 13 | C17: EN 500 R | E17: =IF(D17=0,"0",VLOOKUP(D17,struktura!$B:$D,3,FALSE)) -> 0 | F17: =IF(D17=0,"",24/VLOOKUP(D17,struktura!$B:$F,5,FALSE)) | G17: =VLOOKUP(D17,struktura!$B:$G,6,FALSE) -> 0 | H17: 132400510 | I17: ASM Ohišje Levo 600-IN-E RAL9005 | J17: 1530 | K17: 1 | L17: 132400510 | M17: =IF(L17=0,0,VLOOKUP(L17,struktura!$B:$D,3,FALSE)) -> ASM Ohišje Levo 600-IN-E RAL9005 | N17: =IF(L17=0,0,N$1/VLOOKUP(L17,struktura!$B:$F,5,FALSE)) -> 1530 | O17: =VLOOKUP(L17,struktura!$B:$G,6,FALSE) -> 1 | P17: 132400510 | Q17: =IF(P17=0,0,VLOOKUP(P17,struktura!$B:$D,3,FALSE)) -> ASM Ohišje Levo 600-IN-E RAL9005 | R17: =IF(P17=0,0,R$1/VLOOKUP(P17,struktura!$B:$F,5,FALSE)) -> 1530 | S17: =VLOOKUP(P17,struktura!$B:$G,6,FALSE) -> 1 | T17: 132400616 | U17: =IF(T17=0,0,VLOOKUP(T17,struktura!$B:$D,3,FALSE)) -> ASM Plošča Sprednja 600RNA black | V17: =IF(T17=0,0,V$1/VLOOKUP(T17,struktura!$B:$F,5,FALSE)) -> 1345.7944 | W17: =VLOOKUP(T17,struktura!$B:$G,6,FALSE) -> 1 | X17: 132400535 | Y17: =IF(X17=0,0,VLOOKUP(X17,struktura!$B:$D,3,FALSE)) -> ASM Plošča Sprednja 600 CL-E | Z17: =IF(X17=0,0,Z$1/VLOOKUP(X17,struktura!$B:$F,5,FALSE)) -> 1500 | AA17: =VLOOKUP(X17,struktura!$B:$G,6,FALSE) -> 1.5 | AB17: 132400535 | AC17: =IF(AB17=0,0,VLOOKUP(AB17,struktura!$B:$D,3,FALSE)) -> ASM Plošča Sprednja 600 CL-E | AD17: =IF(AB17=0,0,AD$1/VLOOKUP(AB17,struktura!$B:$F,5,FALSE)) -> 1500 | AE17: =VLOOKUP(AB17,struktura!$B:$G,6,FALSE) -> 1.5 | AF17: 132400535 | AG17: =IF(AF17=0,0,VLOOKUP(AF17,struktura!$B:$D,3,FALSE)) -> ASM Plošča Sprednja 600 CL-E | AH17: =IF(AF17=0,0,AH$1/VLOOKUP(AF17,struktura!$B:$F,5,FALSE)) -> 1500 | AI17: =VLOOKUP(AF17,struktura!$B:$G,6,FALSE) -> 1.5 | AJ17: 132400535 | AK17: =IF(AJ17=0,0,VLOOKUP(AJ17,struktura!$B:$D,3,FALSE)) -> ASM Plošča Sprednja 600 CL-E | AL17: =IF(AJ17=0,0,AL$1/VLOOKUP(AJ17,struktura!$B:$F,5,FALSE)) -> 1500 | AM17: =VLOOKUP(AJ17,struktura!$B:$G,6,FALSE) -> 1.5 | AN17: 132110521 | AO17: =IF(AN17=0,0,VLOOKUP(AN17,struktura!$B:$D,3,FALSE)) -> ASM Plošča Sprednja 600 RAL7045 sur za lakiranje | AP17: =IF(AN17=0,0,AP$1/VLOOKUP(AN17,struktura!$B:$F,5,FALSE)) -> 1345.7944 | AQ17: =VLOOKUP(AN17,struktura!$B:$G,6,FALSE) -> 1 | AR17: 132110521 | AS17: =IF(AR17=0,0,VLOOKUP(AR17,struktura!$B:$D,3,FALSE)) -> ASM Plošča Sprednja 600 RAL7045 sur za lakiranje | AT17: =IF(AR17=0,0,AT$1/VLOOKUP(AR17,struktura!$B:$F,5,FALSE)) -> 1345.7944 | AU17: =VLOOKUP(AR17,struktura!$B:$G,6,FALSE) -> 1 | AW17: =IF(AV17=0,0,VLOOKUP(AV17,struktura!$B:$D,3,FALSE)) -> 0 | AX17: =IF(AV17=0,0,AX$1/VLOOKUP(AV17,struktura!$B:$F,5,FALSE)) -> 0 | AY17: =VLOOKUP(AV17,struktura!$B:$G,6,FALSE) -> 0 | BA17: =IF(AZ17=0,0,VLOOKUP(AZ17,struktura!$B:$D,3,FALSE)) -> 0 | BB17: =IF(AZ17=0,0,BB$1/VLOOKUP(AZ17,struktura!$B:$F,5,FALSE)) -> 0 | BC17: =VLOOKUP(AZ17,struktura!$B:$G,6,FALSE) -> 0 | BD17: 132100504 | BE17: =IF(BD17=0,0,VLOOKUP(BD17,struktura!$B:$D,3,FALSE)) -> Ohišje levo 600-CL RAL9005 | BF17: =IF(BD17=0,0,BF$1/VLOOKUP(BD17,struktura!$B:$F,5,FALSE)) -> 1627.1186 | BG17: =VLOOKUP(BD17,struktura!$B:$G,6,FALSE) -> 1 | BH17: 132100504 | BI17: =IF(BH17=0,0,VLOOKUP(BH17,struktura!$B:$D,3,FALSE)) -> Ohišje levo 600-CL RAL9005 | BJ17: =IF(BH17=0,0,BJ$1/VLOOKUP(BH17,struktura!$B:$F,5,FALSE)) -> 1627.1186 | BK17: =VLOOKUP(BH17,struktura!$B:$G,6,FALSE) -> 1 | BL17: 132100504 | BM17: =IF(BL17=0,0,VLOOKUP(BL17,struktura!$B:$D,3,FALSE)) -> Ohišje levo 600-CL RAL9005 | BN17: =IF(BL17=0,0,BN$1/VLOOKUP(BL17,struktura!$B:$F,5,FALSE)) -> 1627.1186 | BO17: =VLOOKUP(BL17,struktura!$B:$G,6,FALSE) -> 1 | BP17: 132100504 | BQ17: =IF(BP17=0,0,VLOOKUP(BP17,struktura!$B:$D,3,FALSE)) -> Ohišje levo 600-CL RAL9005 | BR17: =IF(BP17=0,0,BR$1/VLOOKUP(BP17,struktura!$B:$F,5,FALSE)) -> 1627.1186 | BS17: =VLOOKUP(BP17,struktura!$B:$G,6,FALSE) -> 1 | BT17: 132100504 | BU17: =IF(BT17=0,0,VLOOKUP(BT17,struktura!$B:$D,3,FALSE)) -> Ohišje levo 600-CL RAL9005 | BV17: =IF(BT17=0,0,BV$1/VLOOKUP(BT17,struktura!$B:$F,5,FALSE)) -> 1627.1186 | BW17: =VLOOKUP(BT17,struktura!$B:$G,6,FALSE) -> 1 | BX17: 132400516 | BY17: =IF(BX17=0,0,VLOOKUP(BX17,struktura!$B:$D,3,FALSE)) -> ASM Ohišje desno 600 RAL9005 | BZ17: =IF(BX17=0,0,BZ$1/VLOOKUP(BX17,struktura!$B:$F,5,FALSE)) -> 1590 | CA17: =VLOOKUP(BX17,struktura!$B:$G,6,FALSE) -> 1.5 | CB17: 132400516 | CC17: =IF(CB17=0,0,VLOOKUP(CB17,struktura!$B:$D,3,FALSE)) -> ASM Ohišje desno 600 RAL9005 | CD17: =IF(CB17=0,0,CD$1/VLOOKUP(CB17,struktura!$B:$F,5,FALSE)) -> 1590 | CE17: =VLOOKUP(CB17,struktura!$B:$G,6,FALSE) -> 1.5 | CF17: 132400516 | CG17: =IF(CF17=0,0,VLOOKUP(CF17,struktura!$B:$D,3,FALSE)) -> ASM Ohišje desno 600 RAL9005 | CH17: =IF(CF17=0,0,CH$1/VLOOKUP(CF17,struktura!$B:$F,5,FALSE)) -> 1590 | CI17: =VLOOKUP(CF17,struktura!$B:$G,6,FALSE) -> 1.5 | CJ17: 132400516 | CK17: =IF(CJ17=0,0,VLOOKUP(CJ17,struktura!$B:$D,3,FALSE)) -> ASM Ohišje desno 600 RAL9005 | CL17: =IF(CJ17=0,0,CL$1/VLOOKUP(CJ17,struktura!$B:$F,5,FALSE)) -> 1590 | CM17: =VLOOKUP(CJ17,struktura!$B:$G,6,FALSE) -> 1.5 | CN17: 132400516 | CO17: =IF(CN17=0,0,VLOOKUP(CN17,struktura!$B:$D,3,FALSE)) -> ASM Ohišje desno 600 RAL9005 | CP17: =IF(CN17=0,0,CP$1/VLOOKUP(CN17,struktura!$B:$F,5,FALSE)) -> 1590 | CQ17: =VLOOKUP(CN17,struktura!$B:$G,6,FALSE) -> 1.5 | CR17: 132400516 | CS17: =IF(CR17=0,0,VLOOKUP(CR17,struktura!$B:$D,3,FALSE)) -> ASM Ohišje desno 600 RAL9005 | CT17: =IF(CR17=0,0,CT$1/VLOOKUP(CR17,struktura!$B:$F,5,FALSE)) -> 1590 | CU17: =VLOOKUP(CR17,struktura!$B:$G,6,FALSE) -> 1.5 | CW17: =IF(CV17=0,0,VLOOKUP(CV17,struktura!$B:$D,3,FALSE)) -> 0 | CX17: =IF(CV17=0,0,CX$1/VLOOKUP(CV17,struktura!$B:$F,5,FALSE)) -> 0 | CY17: =VLOOKUP(CV17,struktura!$B:$G,6,FALSE) -> 0 | DE17: =IF(DD17=0,0,VLOOKUP(DD17,struktura!$B:$D,3,FALSE)) -> 0 | DF17: =IF(DD17=0,0,DF$1/VLOOKUP(DD17,struktura!$B:$F,5,FALSE)) -> 0 | DG17: =VLOOKUP(DD17,struktura!$B:$G,6,FALSE) -> 0 | DI17: =IF(DH17=0,0,VLOOKUP(DH17,struktura!$B:$D,3,FALSE)) -> 0 | DJ17: =IF(DH17=0,0,DJ$1/VLOOKUP(DH17,struktura!$B:$F,5,FALSE)) -> 0 | DK17: =VLOOKUP(DH17,struktura!$B:$G,6,FALSE) -> 0 | DM17: =IF(DL17=0,0,VLOOKUP(DL17,struktura!$B:$D,3,FALSE)) -> 0 | DN17: =IF(DL17=0,0,DN$1/VLOOKUP(DL17,struktura!$B:$F,5,FALSE)) -> 0 | DO17: =VLOOKUP(DL17,struktura!$B:$G,6,FALSE) -> 0 | DQ17: =IF(DP17=0,0,VLOOKUP(DP17,struktura!$B:$D,3,FALSE)) -> 0 | DR17: =IF(DP17=0,0,DR$1/VLOOKUP(DP17,struktura!$B:$F,5,FALSE)) -> 0 | DS17: =VLOOKUP(DP17,struktura!$B:$G,6,FALSE) -> 0
H18: P250809810 | T18: vzorčenje mletina , 200kosP250810092 +500 lakiranje P251108513, P250810975 | X18: vzorčenje 20 kos nov potisk , P250809932 serija 4.000 - 3 dni | AN18: P251009257 serija 2.000 kos (sur za redno + facelift) | AV18: 5S delavnica - 2 dni
B19: 4 | C19: EN 600 R | E19: =IF(D19=0,"0",VLOOKUP(D19,struktura!$B:$D,3,FALSE)) -> 0 | F19: =IF(D19=0,"",24/VLOOKUP(D19,struktura!$B:$F,5,FALSE)) | G19: =VLOOKUP(D19,struktura!$B:$G,6,FALSE) -> 0 | H19: 200100040 | I19: Vertikalni profil vrat BIO2 MF des. | J19: 3750 | K19: 0.25 | L19: 200100040 | M19: =IF(L19=0,0,VLOOKUP(L19,struktura!$B:$D,3,FALSE)) -> Vertikalni profil vrat BIO2 MF des. | N19: =IF(L19=0,0,N$1/VLOOKUP(L19,struktura!$B:$F,5,FALSE)) -> 3750 | O19: =VLOOKUP(L19,struktura!$B:$G,6,FALSE) -> 0.25 | Q19: =IF(P19=0,0,VLOOKUP(P19,struktura!$B:$D,3,FALSE)) -> 0 | R19: =IF(P19=0,0,R$1/VLOOKUP(P19,struktura!$B:$F,5,FALSE)) -> 0 | S19: =VLOOKUP(P19,struktura!$B:$G,6,FALSE) -> 0 | T19: 200100042 | U19: =IF(T19=0,0,VLOOKUP(T19,struktura!$B:$D,3,FALSE)) -> Vertikalni profil vrat BIO2 PY des. | V19: =IF(T19=0,0,V$1/VLOOKUP(T19,struktura!$B:$F,5,FALSE)) -> 3750 | W19: =VLOOKUP(T19,struktura!$B:$G,6,FALSE) -> 0.25 | X19: 200100042 | Y19: =IF(X19=0,0,VLOOKUP(X19,struktura!$B:$D,3,FALSE)) -> Vertikalni profil vrat BIO2 PY des. | Z19: =IF(X19=0,0,Z$1/VLOOKUP(X19,struktura!$B:$F,5,FALSE)) -> 3750 | AA19: =VLOOKUP(X19,struktura!$B:$G,6,FALSE) -> 0.25 | AB19: 200100042 | AC19: =IF(AB19=0,0,VLOOKUP(AB19,struktura!$B:$D,3,FALSE)) -> Vertikalni profil vrat BIO2 PY des. | AD19: =IF(AB19=0,0,AD$1/VLOOKUP(AB19,struktura!$B:$F,5,FALSE)) -> 3750 | AE19: =VLOOKUP(AB19,struktura!$B:$G,6,FALSE) -> 0.25 | AF19: 200100040 | AG19: =IF(AF19=0,0,VLOOKUP(AF19,struktura!$B:$D,3,FALSE)) -> Vertikalni profil vrat BIO2 MF des. | AH19: =IF(AF19=0,0,AH$1/VLOOKUP(AF19,struktura!$B:$F,5,FALSE)) -> 3750 | AI19: =VLOOKUP(AF19,struktura!$B:$G,6,FALSE) -> 0.25 | AJ19: 200100040 | AK19: =IF(AJ19=0,0,VLOOKUP(AJ19,struktura!$B:$D,3,FALSE)) -> Vertikalni profil vrat BIO2 MF des. | AL19: =IF(AJ19=0,0,AL$1/VLOOKUP(AJ19,struktura!$B:$F,5,FALSE)) -> 3750 | AM19: =VLOOKUP(AJ19,struktura!$B:$G,6,FALSE) -> 0.25 | AN19: 200100040 | AO19: =IF(AN19=0,0,VLOOKUP(AN19,struktura!$B:$D,3,FALSE)) -> Vertikalni profil vrat BIO2 MF des. | AP19: =IF(AN19=0,0,AP$1/VLOOKUP(AN19,struktura!$B:$F,5,FALSE)) -> 3750 | AQ19: =VLOOKUP(AN19,struktura!$B:$G,6,FALSE) -> 0.25 | AR19: 200100040 | AS19: =IF(AR19=0,0,VLOOKUP(AR19,struktura!$B:$D,3,FALSE)) -> Vertikalni profil vrat BIO2 MF des. | AT19: =IF(AR19=0,0,AT$1/VLOOKUP(AR19,struktura!$B:$F,5,FALSE)) -> 3750 | AU19: =VLOOKUP(AR19,struktura!$B:$G,6,FALSE) -> 0.25 | AV19: 200100040 | AW19: =IF(AV19=0,0,VLOOKUP(AV19,struktura!$B:$D,3,FALSE)) -> Vertikalni profil vrat BIO2 MF des. | AX19: =IF(AV19=0,0,AX$1/VLOOKUP(AV19,struktura!$B:$F,5,FALSE)) -> 3750 | AY19: =VLOOKUP(AV19,struktura!$B:$G,6,FALSE) -> 0.25 | AZ19: 200100040 | BA19: =IF(AZ19=0,0,VLOOKUP(AZ19,struktura!$B:$D,3,FALSE)) -> Vertikalni profil vrat BIO2 MF des. | BB19: =IF(AZ19=0,0,BB$1/VLOOKUP(AZ19,struktura!$B:$F,5,FALSE)) -> 3750 | BC19: =VLOOKUP(AZ19,struktura!$B:$G,6,FALSE) -> 0.25 | BD19: 200100040 | BE19: =IF(BD19=0,0,VLOOKUP(BD19,struktura!$B:$D,3,FALSE)) -> Vertikalni profil vrat BIO2 MF des. | BF19: =IF(BD19=0,0,BF$1/VLOOKUP(BD19,struktura!$B:$F,5,FALSE)) -> 3750 | BG19: =VLOOKUP(BD19,struktura!$B:$G,6,FALSE) -> 0.25 | BH19: 200100040 | BI19: =IF(BH19=0,0,VLOOKUP(BH19,struktura!$B:$D,3,FALSE)) -> Vertikalni profil vrat BIO2 MF des. | BJ19: =IF(BH19=0,0,BJ$1/VLOOKUP(BH19,struktura!$B:$F,5,FALSE)) -> 3750 | BK19: =VLOOKUP(BH19,struktura!$B:$G,6,FALSE) -> 0.25 | BL19: 200100040 | BM19: =IF(BL19=0,0,VLOOKUP(BL19,struktura!$B:$D,3,FALSE)) -> Vertikalni profil vrat BIO2 MF des. | BN19: =IF(BL19=0,0,BN$1/VLOOKUP(BL19,struktura!$B:$F,5,FALSE)) -> 3750 | BO19: =VLOOKUP(BL19,struktura!$B:$G,6,FALSE) -> 0.25 | BQ19: =IF(BP19=0,0,VLOOKUP(BP19,struktura!$B:$D,3,FALSE)) -> 0 | BR19: =IF(BP19=0,0,BR$1/VLOOKUP(BP19,struktura!$B:$F,5,FALSE)) -> 0 | BS19: =VLOOKUP(BP19,struktura!$B:$G,6,FALSE) -> 0 | BU19: =IF(BT19=0,0,VLOOKUP(BT19,struktura!$B:$D,3,FALSE)) -> 0 | BV19: =IF(BT19=0,0,BV$1/VLOOKUP(BT19,struktura!$B:$F,5,FALSE)) -> 0 | BW19: =VLOOKUP(BT19,struktura!$B:$G,6,FALSE) -> 0 | BY19: =IF(BX19=0,0,VLOOKUP(BX19,struktura!$B:$D,3,FALSE)) -> 0 | BZ19: =IF(BX19=0,0,BZ$1/VLOOKUP(BX19,struktura!$B:$F,5,FALSE)) -> 0 | CA19: =VLOOKUP(BX19,struktura!$B:$G,6,FALSE) -> 0 | CC19: =IF(CB19=0,0,VLOOKUP(CB19,struktura!$B:$D,3,FALSE)) -> 0 | CD19: =IF(CB19=0,0,CD$1/VLOOKUP(CB19,struktura!$B:$F,5,FALSE)) -> 0 | CE19: =VLOOKUP(CB19,struktura!$B:$G,6,FALSE) -> 0 | CG19: =IF(CF19=0,0,VLOOKUP(CF19,struktura!$B:$D,3,FALSE)) -> 0 | CH19: =IF(CF19=0,0,CH$1/VLOOKUP(CF19,struktura!$B:$F,5,FALSE)) -> 0 | CI19: =VLOOKUP(CF19,struktura!$B:$G,6,FALSE) -> 0 | CK19: =IF(CJ19=0,0,VLOOKUP(CJ19,struktura!$B:$D,3,FALSE)) -> 0 | CL19: =IF(CJ19=0,0,CL$1/VLOOKUP(CJ19,struktura!$B:$F,5,FALSE)) -> 0 | CM19: =VLOOKUP(CJ19,struktura!$B:$G,6,FALSE) -> 0 | CN19: 200100040 | CO19: =IF(CN19=0,0,VLOOKUP(CN19,struktura!$B:$D,3,FALSE)) -> Vertikalni profil vrat BIO2 MF des. | CP19: =IF(CN19=0,0,CP$1/VLOOKUP(CN19,struktura!$B:$F,5,FALSE)) -> 3750 | CQ19: =VLOOKUP(CN19,struktura!$B:$G,6,FALSE) -> 0.25 | CR19: 200100040 | CS19: =IF(CR19=0,0,VLOOKUP(CR19,struktura!$B:$D,3,FALSE)) -> Vertikalni profil vrat BIO2 MF des. | CT19: =IF(CR19=0,0,CT$1/VLOOKUP(CR19,struktura!$B:$F,5,FALSE)) -> 3750 | CU19: =VLOOKUP(CR19,struktura!$B:$G,6,FALSE) -> 0.25 | CV19: 200100040 | CW19: =IF(CV19=0,0,VLOOKUP(CV19,struktura!$B:$D,3,FALSE)) -> Vertikalni profil vrat BIO2 MF des. | CX19: =IF(CV19=0,0,CX$1/VLOOKUP(CV19,struktura!$B:$F,5,FALSE)) -> 3750 | CY19: =VLOOKUP(CV19,struktura!$B:$G,6,FALSE) -> 0.25 | DE19: =IF(DD19=0,0,VLOOKUP(DD19,struktura!$B:$D,3,FALSE)) -> 0 | DF19: =IF(DD19=0,0,DF$1/VLOOKUP(DD19,struktura!$B:$F,5,FALSE)) -> 0 | DG19: =VLOOKUP(DD19,struktura!$B:$G,6,FALSE) -> 0 | DI19: =IF(DH19=0,0,VLOOKUP(DH19,struktura!$B:$D,3,FALSE)) -> 0 | DJ19: =IF(DH19=0,0,DJ$1/VLOOKUP(DH19,struktura!$B:$F,5,FALSE)) -> 0 | DK19: =VLOOKUP(DH19,struktura!$B:$G,6,FALSE) -> 0 | DM19: =IF(DL19=0,0,VLOOKUP(DL19,struktura!$B:$D,3,FALSE)) -> 0 | DN19: =IF(DL19=0,0,DN$1/VLOOKUP(DL19,struktura!$B:$F,5,FALSE)) -> 0 | DO19: =VLOOKUP(DL19,struktura!$B:$G,6,FALSE) -> 0 | DQ19: =IF(DP19=0,0,VLOOKUP(DP19,struktura!$B:$D,3,FALSE)) -> 0 | DR19: =IF(DP19=0,0,DR$1/VLOOKUP(DP19,struktura!$B:$F,5,FALSE)) -> 0 | DS19: =VLOOKUP(DP19,struktura!$B:$G,6,FALSE) -> 0
P20: servis orodja, četrtek menjava materiala | T20: po servisu P250910452, P250810673 | AF20: P250910327 | BP20: orodje na popravilo za 1 teden | BT20: 5S delavnica - 2 dni | CN20: zagon po popravilu orodja
B21: 5 | C21: KM 300 R | E21: =IF(D21=0,"0",VLOOKUP(D21,struktura!$B:$D,3,FALSE)) -> 0 | F21: =IF(D21=0,"",24/VLOOKUP(D21,struktura!$B:$F,5,FALSE)) | G21: =VLOOKUP(D21,struktura!$B:$G,6,FALSE) -> 0 | I21: 0 | J21: 0 | K21: 0 | M21: =IF(L21=0,0,VLOOKUP(L21,struktura!$B:$D,3,FALSE)) -> 0 | N21: =IF(L21=0,0,N$1/VLOOKUP(L21,struktura!$B:$F,5,FALSE)) -> 0 | O21: =VLOOKUP(L21,struktura!$B:$G,6,FALSE) -> 0 | Q21: =IF(P21=0,0,VLOOKUP(P21,struktura!$B:$D,3,FALSE)) -> 0 | R21: =IF(P21=0,0,R$1/VLOOKUP(P21,struktura!$B:$F,5,FALSE)) -> 0 | S21: =VLOOKUP(P21,struktura!$B:$G,6,FALSE) -> 0 | U21: =IF(T21=0,0,VLOOKUP(T21,struktura!$B:$D,3,FALSE)) -> 0 | V21: =IF(T21=0,0,V$1/VLOOKUP(T21,struktura!$B:$F,5,FALSE)) -> 0 | W21: =VLOOKUP(T21,struktura!$B:$G,6,FALSE) -> 0 | Y21: =IF(X21=0,0,VLOOKUP(X21,struktura!$B:$D,3,FALSE)) -> 0 | Z21: =IF(X21=0,0,Z$1/VLOOKUP(X21,struktura!$B:$F,5,FALSE)) -> 0 | AA21: =VLOOKUP(X21,struktura!$B:$G,6,FALSE) -> 0 | AC21: =IF(AB21=0,0,VLOOKUP(AB21,struktura!$B:$D,3,FALSE)) -> 0 | AD21: =IF(AB21=0,0,AD$1/VLOOKUP(AB21,struktura!$B:$F,5,FALSE)) -> 0 | AE21: =VLOOKUP(AB21,struktura!$B:$G,6,FALSE) -> 0 | AG21: =IF(AF21=0,0,VLOOKUP(AF21,struktura!$B:$D,3,FALSE)) -> 0 | AH21: =IF(AF21=0,0,AH$1/VLOOKUP(AF21,struktura!$B:$F,5,FALSE)) -> 0 | AI21: =VLOOKUP(AF21,struktura!$B:$G,6,FALSE) -> 0 | AK21: =IF(AJ21=0,0,VLOOKUP(AJ21,struktura!$B:$D,3,FALSE)) -> 0 | AL21: =IF(AJ21=0,0,AL$1/VLOOKUP(AJ21,struktura!$B:$F,5,FALSE)) -> 0 | AM21: =VLOOKUP(AJ21,struktura!$B:$G,6,FALSE) -> 0 | AO21: =IF(AN21=0,0,VLOOKUP(AN21,struktura!$B:$D,3,FALSE)) -> 0 | AP21: =IF(AN21=0,0,AP$1/VLOOKUP(AN21,struktura!$B:$F,5,FALSE)) -> 0 | AQ21: =VLOOKUP(AN21,struktura!$B:$G,6,FALSE) -> 0 | AS21: =IF(AR21=0,0,VLOOKUP(AR21,struktura!$B:$D,3,FALSE)) -> 0 | AT21: =IF(AR21=0,0,AT$1/VLOOKUP(AR21,struktura!$B:$F,5,FALSE)) -> 0 | AU21: =VLOOKUP(AR21,struktura!$B:$G,6,FALSE) -> 0 | AW21: =IF(AV21=0,0,VLOOKUP(AV21,struktura!$B:$D,3,FALSE)) -> 0 | AX21: =IF(AV21=0,0,AX$1/VLOOKUP(AV21,struktura!$B:$F,5,FALSE)) -> 0 | AY21: =VLOOKUP(AV21,struktura!$B:$G,6,FALSE) -> 0 | BA21: =IF(AZ21=0,0,VLOOKUP(AZ21,struktura!$B:$D,3,FALSE)) -> 0 | BB21: =IF(AZ21=0,0,BB$1/VLOOKUP(AZ21,struktura!$B:$F,5,FALSE)) -> 0 | BC21: =VLOOKUP(AZ21,struktura!$B:$G,6,FALSE) -> 0 | BE21: =IF(BD21=0,0,VLOOKUP(BD21,struktura!$B:$D,3,FALSE)) -> 0 | BF21: =IF(BD21=0,0,BF$1/VLOOKUP(BD21,struktura!$B:$F,5,FALSE)) -> 0 | BG21: =VLOOKUP(BD21,struktura!$B:$G,6,FALSE) -> 0 | BI21: =IF(BH21=0,0,VLOOKUP(BH21,struktura!$B:$D,3,FALSE)) -> 0 | BJ21: =IF(BH21=0,0,BJ$1/VLOOKUP(BH21,struktura!$B:$F,5,FALSE)) -> 0 | BK21: =VLOOKUP(BH21,struktura!$B:$G,6,FALSE) -> 0 | BM21: =IF(BL21=0,0,VLOOKUP(BL21,struktura!$B:$D,3,FALSE)) -> 0 | BN21: =IF(BL21=0,0,BN$1/VLOOKUP(BL21,struktura!$B:$F,5,FALSE)) -> 0 | BO21: =VLOOKUP(BL21,struktura!$B:$G,6,FALSE) -> 0 | BQ21: =IF(BP21=0,0,VLOOKUP(BP21,struktura!$B:$D,3,FALSE)) -> 0 | BR21: =IF(BP21=0,0,BR$1/VLOOKUP(BP21,struktura!$B:$F,5,FALSE)) -> 0 | BS21: =VLOOKUP(BP21,struktura!$B:$G,6,FALSE) -> 0 | BU21: =IF(BT21=0,0,VLOOKUP(BT21,struktura!$B:$D,3,FALSE)) -> 0 | BV21: =IF(BT21=0,0,BV$1/VLOOKUP(BT21,struktura!$B:$F,5,FALSE)) -> 0 | BW21: =VLOOKUP(BT21,struktura!$B:$G,6,FALSE) -> 0 | BY21: =IF(BX21=0,0,VLOOKUP(BX21,struktura!$B:$D,3,FALSE)) -> 0 | BZ21: =IF(BX21=0,0,BZ$1/VLOOKUP(BX21,struktura!$B:$F,5,FALSE)) -> 0 | CA21: =VLOOKUP(BX21,struktura!$B:$G,6,FALSE) -> 0 | CC21: =IF(CB21=0,0,VLOOKUP(CB21,struktura!$B:$D,3,FALSE)) -> 0 | CD21: =IF(CB21=0,0,CD$1/VLOOKUP(CB21,struktura!$B:$F,5,FALSE)) -> 0 | CE21: =VLOOKUP(CB21,struktura!$B:$G,6,FALSE) -> 0 | CG21: =IF(CF21=0,0,VLOOKUP(CF21,struktura!$B:$D,3,FALSE)) -> 0 | CH21: =IF(CF21=0,0,CH$1/VLOOKUP(CF21,struktura!$B:$F,5,FALSE)) -> 0 | CI21: =VLOOKUP(CF21,struktura!$B:$G,6,FALSE) -> 0 | CK21: =IF(CJ21=0,0,VLOOKUP(CJ21,struktura!$B:$D,3,FALSE)) -> 0 | CL21: =IF(CJ21=0,0,CL$1/VLOOKUP(CJ21,struktura!$B:$F,5,FALSE)) -> 0 | CM21: =VLOOKUP(CJ21,struktura!$B:$G,6,FALSE) -> 0 | CO21: =IF(CN21=0,0,VLOOKUP(CN21,struktura!$B:$D,3,FALSE)) -> 0 | CP21: =IF(CN21=0,0,CP$1/VLOOKUP(CN21,struktura!$B:$F,5,FALSE)) -> 0 | CQ21: =VLOOKUP(CN21,struktura!$B:$G,6,FALSE) -> 0 | CS21: =IF(CR21=0,0,VLOOKUP(CR21,struktura!$B:$D,3,FALSE)) -> 0 | CT21: =IF(CR21=0,0,CT$1/VLOOKUP(CR21,struktura!$B:$F,5,FALSE)) -> 0 | CU21: =VLOOKUP(CR21,struktura!$B:$G,6,FALSE) -> 0 | CW21: =IF(CV21=0,0,VLOOKUP(CV21,struktura!$B:$D,3,FALSE)) -> 0 | CX21: =IF(CV21=0,0,CX$1/VLOOKUP(CV21,struktura!$B:$F,5,FALSE)) -> 0 | CY21: =VLOOKUP(CV21,struktura!$B:$G,6,FALSE) -> 0 | DE21: =IF(DD21=0,0,VLOOKUP(DD21,struktura!$B:$D,3,FALSE)) -> 0 | DF21: =IF(DD21=0,0,DF$1/VLOOKUP(DD21,struktura!$B:$F,5,FALSE)) -> 0 | DG21: =VLOOKUP(DD21,struktura!$B:$G,6,FALSE) -> 0 | DI21: =IF(DH21=0,0,VLOOKUP(DH21,struktura!$B:$D,3,FALSE)) -> 0 | DJ21: =IF(DH21=0,0,DJ$1/VLOOKUP(DH21,struktura!$B:$F,5,FALSE)) -> 0 | DK21: =VLOOKUP(DH21,struktura!$B:$G,6,FALSE) -> 0 | DM21: =IF(DL21=0,0,VLOOKUP(DL21,struktura!$B:$D,3,FALSE)) -> 0 | DN21: =IF(DL21=0,0,DN$1/VLOOKUP(DL21,struktura!$B:$F,5,FALSE)) -> 0 | DO21: =VLOOKUP(DL21,struktura!$B:$G,6,FALSE) -> 0 | DQ21: =IF(DP21=0,0,VLOOKUP(DP21,struktura!$B:$D,3,FALSE)) -> 0 | DR21: =IF(DP21=0,0,DR$1/VLOOKUP(DP21,struktura!$B:$F,5,FALSE)) -> 0 | DS21: =VLOOKUP(DP21,struktura!$B:$G,6,FALSE) -> 0
BD22: 5S delavnica - 2 dni
A23: HALA 1 | B23: 6 | C23: KM 200 R | E23: =IF(D23=0,"0",VLOOKUP(D23,struktura!$B:$D,3,FALSE)) -> 0 | F23: =IF(D23=0,"",24/VLOOKUP(D23,struktura!$B:$F,5,FALSE)) | G23: =VLOOKUP(D23,struktura!$B:$G,6,FALSE) -> 0 | H23: 132110684 | I23: Levi pokrov ohišja K10_Ver.01_sur.1_x000D_ Sur. za vroči tisk | J23: 1680 | K23: 0.5 | L23: 132100490 | M23: =IF(L23=0,0,VLOOKUP(L23,struktura!$B:$D,3,FALSE)) -> BUS CASE BOTTOM V2 | N23: =IF(L23=0,0,N$1/VLOOKUP(L23,struktura!$B:$F,5,FALSE)) -> 3130.4348 | O23: =VLOOKUP(L23,struktura!$B:$G,6,FALSE) -> 0.5 | P23: 132100490 | Q23: =IF(P23=0,0,VLOOKUP(P23,struktura!$B:$D,3,FALSE)) -> BUS CASE BOTTOM V2 | R23: =IF(P23=0,0,R$1/VLOOKUP(P23,struktura!$B:$F,5,FALSE)) -> 3130.4348 | S23: =VLOOKUP(P23,struktura!$B:$G,6,FALSE) -> 0.5 | T23: 132100490 | U23: =IF(T23=0,0,VLOOKUP(T23,struktura!$B:$D,3,FALSE)) -> BUS CASE BOTTOM V2 | V23: =IF(T23=0,0,V$1/VLOOKUP(T23,struktura!$B:$F,5,FALSE)) -> 3130.4348 | W23: =VLOOKUP(T23,struktura!$B:$G,6,FALSE) -> 0.5 | X23: 132100490 | Y23: =IF(X23=0,0,VLOOKUP(X23,struktura!$B:$D,3,FALSE)) -> BUS CASE BOTTOM V2 | Z23: =IF(X23=0,0,Z$1/VLOOKUP(X23,struktura!$B:$F,5,FALSE)) -> 3130.4348 | AA23: =VLOOKUP(X23,struktura!$B:$G,6,FALSE) -> 0.5 | AB23: 132100490 | AC23: =IF(AB23=0,0,VLOOKUP(AB23,struktura!$B:$D,3,FALSE)) -> BUS CASE BOTTOM V2 | AD23: =IF(AB23=0,0,AD$1/VLOOKUP(AB23,struktura!$B:$F,5,FALSE)) -> 3130.4348 | AE23: =VLOOKUP(AB23,struktura!$B:$G,6,FALSE) -> 0.5 | AF23: 132100490 | AG23: =IF(AF23=0,0,VLOOKUP(AF23,struktura!$B:$D,3,FALSE)) -> BUS CASE BOTTOM V2 | AH23: =IF(AF23=0,0,AH$1/VLOOKUP(AF23,struktura!$B:$F,5,FALSE)) -> 3130.4348 | AI23: =VLOOKUP(AF23,struktura!$B:$G,6,FALSE) -> 0.5 | AJ23: 132100490 | AK23: =IF(AJ23=0,0,VLOOKUP(AJ23,struktura!$B:$D,3,FALSE)) -> BUS CASE BOTTOM V2 | AL23: =IF(AJ23=0,0,AL$1/VLOOKUP(AJ23,struktura!$B:$F,5,FALSE)) -> 3130.4348 | AM23: =VLOOKUP(AJ23,struktura!$B:$G,6,FALSE) -> 0.5 | AN23: 132100490 | AO23: =IF(AN23=0,0,VLOOKUP(AN23,struktura!$B:$D,3,FALSE)) -> BUS CASE BOTTOM V2 | AP23: =IF(AN23=0,0,AP$1/VLOOKUP(AN23,struktura!$B:$F,5,FALSE)) -> 3130.4348 | AQ23: =VLOOKUP(AN23,struktura!$B:$G,6,FALSE) -> 0.5 | AS23: =IF(AR23=0,0,VLOOKUP(AR23,struktura!$B:$D,3,FALSE)) -> 0 | AT23: =IF(AR23=0,0,AT$1/VLOOKUP(AR23,struktura!$B:$F,5,FALSE)) -> 0 | AU23: =VLOOKUP(AR23,struktura!$B:$G,6,FALSE) -> 0 | AV23: 132100490 | AW23: =IF(AV23=0,0,VLOOKUP(AV23,struktura!$B:$D,3,FALSE)) -> BUS CASE BOTTOM V2 | AX23: =IF(AV23=0,0,AX$1/VLOOKUP(AV23,struktura!$B:$F,5,FALSE)) -> 3130.4348 | AY23: =VLOOKUP(AV23,struktura!$B:$G,6,FALSE) -> 0.5 | AZ23: 132100490 | BA23: =IF(AZ23=0,0,VLOOKUP(AZ23,struktura!$B:$D,3,FALSE)) -> BUS CASE BOTTOM V2 | BB23: =IF(AZ23=0,0,BB$1/VLOOKUP(AZ23,struktura!$B:$F,5,FALSE)) -> 3130.4348 | BC23: =VLOOKUP(AZ23,struktura!$B:$G,6,FALSE) -> 0.5 | BD23: 132100490 | BE23: =IF(BD23=0,0,VLOOKUP(BD23,struktura!$B:$D,3,FALSE)) -> BUS CASE BOTTOM V2 | BF23: =IF(BD23=0,0,BF$1/VLOOKUP(BD23,struktura!$B:$F,5,FALSE)) -> 3130.4348 | BG23: =VLOOKUP(BD23,struktura!$B:$G,6,FALSE) -> 0.5 | BH23: 132100490 | BI23: =IF(BH23=0,0,VLOOKUP(BH23,struktura!$B:$D,3,FALSE)) -> BUS CASE BOTTOM V2 | BJ23: =IF(BH23=0,0,BJ$1/VLOOKUP(BH23,struktura!$B:$F,5,FALSE)) -> 3130.4348 | BK23: =VLOOKUP(BH23,struktura!$B:$G,6,FALSE) -> 0.5 | BM23: =IF(BL23=0,0,VLOOKUP(BL23,struktura!$B:$D,3,FALSE)) -> 0 | BN23: =IF(BL23=0,0,BN$1/VLOOKUP(BL23,struktura!$B:$F,5,FALSE)) -> 0 | BO23: =VLOOKUP(BL23,struktura!$B:$G,6,FALSE) -> 0 | BQ23: =IF(BP23=0,0,VLOOKUP(BP23,struktura!$B:$D,3,FALSE)) -> 0 | BR23: =IF(BP23=0,0,BR$1/VLOOKUP(BP23,struktura!$B:$F,5,FALSE)) -> 0 | BS23: =VLOOKUP(BP23,struktura!$B:$G,6,FALSE) -> 0 | BU23: =IF(BT23=0,0,VLOOKUP(BT23,struktura!$B:$D,3,FALSE)) -> 0 | BV23: =IF(BT23=0,0,BV$1/VLOOKUP(BT23,struktura!$B:$F,5,FALSE)) -> 0 | BW23: =VLOOKUP(BT23,struktura!$B:$G,6,FALSE) -> 0 | BY23: =IF(BX23=0,0,VLOOKUP(BX23,struktura!$B:$D,3,FALSE)) -> 0 | BZ23: =IF(BX23=0,0,BZ$1/VLOOKUP(BX23,struktura!$B:$F,5,FALSE)) -> 0 | CA23: =VLOOKUP(BX23,struktura!$B:$G,6,FALSE) -> 0 | CC23: =IF(CB23=0,0,VLOOKUP(CB23,struktura!$B:$D,3,FALSE)) -> 0 | CD23: =IF(CB23=0,0,CD$1/VLOOKUP(CB23,struktura!$B:$F,5,FALSE)) -> 0 | CE23: =VLOOKUP(CB23,struktura!$B:$G,6,FALSE) -> 0 | CF23: 132100490 | CG23: =IF(CF23=0,0,VLOOKUP(CF23,struktura!$B:$D,3,FALSE)) -> BUS CASE BOTTOM V2 | CH23: =IF(CF23=0,0,CH$1/VLOOKUP(CF23,struktura!$B:$F,5,FALSE)) -> 3130.4348 | CI23: =VLOOKUP(CF23,struktura!$B:$G,6,FALSE) -> 0.5 | CJ23: 132100490 | CK23: =IF(CJ23=0,0,VLOOKUP(CJ23,struktura!$B:$D,3,FALSE)) -> BUS CASE BOTTOM V2 | CL23: =IF(CJ23=0,0,CL$1/VLOOKUP(CJ23,struktura!$B:$F,5,FALSE)) -> 3130.4348 | CM23: =VLOOKUP(CJ23,struktura!$B:$G,6,FALSE) -> 0.5 | CN23: 132100490 | CO23: =IF(CN23=0,0,VLOOKUP(CN23,struktura!$B:$D,3,FALSE)) -> BUS CASE BOTTOM V2 | CP23: =IF(CN23=0,0,CP$1/VLOOKUP(CN23,struktura!$B:$F,5,FALSE)) -> 3130.4348 | CQ23: =VLOOKUP(CN23,struktura!$B:$G,6,FALSE) -> 0.5 | CR23: 132100490 | CS23: =IF(CR23=0,0,VLOOKUP(CR23,struktura!$B:$D,3,FALSE)) -> BUS CASE BOTTOM V2 | CT23: =IF(CR23=0,0,CT$1/VLOOKUP(CR23,struktura!$B:$F,5,FALSE)) -> 3130.4348 | CU23: =VLOOKUP(CR23,struktura!$B:$G,6,FALSE) -> 0.5 | CV23: 132100490 | CW23: =IF(CV23=0,0,VLOOKUP(CV23,struktura!$B:$D,3,FALSE)) -> BUS CASE BOTTOM V2 | CX23: =IF(CV23=0,0,CX$1/VLOOKUP(CV23,struktura!$B:$F,5,FALSE)) -> 3130.4348 | CY23: =VLOOKUP(CV23,struktura!$B:$G,6,FALSE) -> 0.5 | DE23: =IF(DD23=0,0,VLOOKUP(DD23,struktura!$B:$D,3,FALSE)) -> 0 | DF23: =IF(DD23=0,0,DF$1/VLOOKUP(DD23,struktura!$B:$F,5,FALSE)) -> 0 | DG23: =VLOOKUP(DD23,struktura!$B:$G,6,FALSE) -> 0 | DI23: =IF(DH23=0,0,VLOOKUP(DH23,struktura!$B:$D,3,FALSE)) -> 0 | DJ23: =IF(DH23=0,0,DJ$1/VLOOKUP(DH23,struktura!$B:$F,5,FALSE)) -> 0 | DK23: =VLOOKUP(DH23,struktura!$B:$G,6,FALSE) -> 0 | DM23: =IF(DL23=0,0,VLOOKUP(DL23,struktura!$B:$D,3,FALSE)) -> 0 | DN23: =IF(DL23=0,0,DN$1/VLOOKUP(DL23,struktura!$B:$F,5,FALSE)) -> 0 | DO23: =VLOOKUP(DL23,struktura!$B:$G,6,FALSE) -> 0 | DQ23: =IF(DP23=0,0,VLOOKUP(DP23,struktura!$B:$D,3,FALSE)) -> 0 | DR23: =IF(DP23=0,0,DR$1/VLOOKUP(DP23,struktura!$B:$F,5,FALSE)) -> 0 | DS23: =VLOOKUP(DP23,struktura!$B:$G,6,FALSE) -> 0
L24: P260600750 po popravilu orodja | BL24: 5S delavnica - 2 dni
